Workbook

Sheet 引用文档一览
A1: 引用文档一览
A2: 本ブックが参照した语料文書の一覧。パスは docs/asset 相対。ID の权威源は IDR-01（ID 台账）。
A3: 文書ID | B3: 文書名（ファイル） | C3: パス（docs/asset 相対） | D3: 本ブックでの参照先 | E3: 備考
A4: IDR-01 | B4: interview-portfolio-id-registry.md | C4: requirement-definition-draft/interview-portfolio-id-registry.md | D4: 全体（ID 系列の权威源・实施状态の判定根拠） | E4: V1.4
A5: RD-01 | B5: 01_要件一覧.md | C5: requirement-definition/01_要件一覧.md | D5: 2.要件一覧・5.BIZ一覧（J 列 COUNTIF 键）・14.要件×機能行列（○ 出典）
A6: RD-02 | B6: 02_非機能要件一覧.md | C6: requirement-definition/02_非機能要件一覧.md | D6: 2.要件一覧（NFR 行）
A7: RD-03 | B7: 03_業務一覧.md | C7: requirement-definition/03_業務一覧.md | D7: 5.BIZ一覧
A8: RD-05 | B8: 05_業務ルール一覧.md | C8: requirement-definition/05_業務ルール一覧.md | D8: 6.ルール一覧
A9: RD-06 | B9: 06_用語集.md | C9: requirement-definition/06_用語集.md | D9: 7.用語集
A10: RD-08 | B10: 08_ToBe業務モデルと現状課題.md | C10: requirement-definition/08_ToBe業務モデルと現状課題.md | D10: 12.課題…（ISS）
A11: BD-01 | B11: system-architecture.md | C11: basic-design/system-architecture.md | D11: 8.IF・CD・CF・A一覧（A1〜A4）
A12: BD-02 | B12: function-list.md | C12: basic-design/function-list.md | D12: 3.機能一覧・15.機能×画面行列
A13: BD-04 | B13: screens.md | C13: basic-design/screens.md | D13: 4.画面一覧・15.機能×画面行列
A14: BD-05 | B14: screen-items.md | C14: basic-design/screen-items.md | D14: 11.画面項目・MSG
A15: BD-08 | B15: code-list.md | C15: basic-design/code-list.md | D15: 8.IF・CD・CF・A一覧（CD）
A16: BD-09 | B16: interface-design.md | C16: basic-design/interface-design.md | D16: 8.IF・CD・CF・A一覧（IF） | E16: MV-03 検証日の一次記録は PPT-01/IDR-01
A17: BD-11 | B17: common-design.md | C17: basic-design/common-design.md | D17: 8.IF・CD・CF・A一覧（CF）
A18: DD-04 | B18: unit-test-spec.md | C18: detailed-design/unit-test-spec.md | D18: 10.TC一覧
A19: —（無 ID） | B19: experience-site-mvp-validation.md | C19: experience-site-mvp-validation.md | D19: 9.MV一覧・16.サマリー判定口径
A20: —（無 ID） | B20: interview-portfolio-tech-decisions.md | C20: interview-portfolio-tech-decisions.md | D20: 12.課題…（G/ADR）
A21: CHK-01 | B21: p0-2/interview-portfolio-p02-checklist.md | C21: p0-2/interview-portfolio-p02-checklist.md | D21: 12.課題…（CHK 内部 ID） | E21: V1.7
A22: PPT-01 | B22: interview-portfolio-phase-table.md | C22: interview-portfolio-phase-table.md | D22: 12.課題…（P0-n 工程） | E22: V1.5
A23: — | B23: coverage-matrix-summary.xlsx（雛形） | C23: ../coverage-matrix-summary.xlsx（docs/ 直下） | D23: 全体（書式・式パターンの母体）

Sheet 1.使い方
A1: 要件 × 機能 × 画面 カバレッジ行列テンプレート
A2: 用途：要件定义 / 基本设计阶段，检查「有没有漏配」。橙色底 = 未割当（有漏），绿色底 = OK。
B4: 步骤 | C4: 做什么 | D4: 说明
B5: STEP 1 | C5: 确认「引用文档一览」 | D5: 「引用文档一览」登记本ブック全数据的出典文書清单，与 ID 台账（IDR-01）对应。新建任何 ID 之前，先在此确认定义源是否已登记。
B6: STEP 2 | C6: 填写「2.要件一覧」 | D6: 逐条登记要件，给每个要件一个唯一 ID。分类、优先级、验收条件建议必填——验收条件缺失会导致后期无法判定是否做完。J 列（対応業務 ID）是「5.BIZ一覧」対応要件数 COUNTIF 的集計键，漏填会静默计 0；K 列实施状态按语料进度维护。
B7: STEP 3 | C7: 填写「3.機能一覧」 | D7: 把要件拆解为系统机能。担当ロール 决定后面的权限设计，新規/改修 决定影响范围。
B8: STEP 4 | C8: 填写「4.画面一覧」 | D8: 登记所有画面，含弹窗、确认页、错误页。漏登记画面是测试阶段缺陷的高发原因。
B9: STEP 5 | C9: 填写一览系台账「5.BIZ一覧」〜「13.文書ID台帳」 | D9: 填写一览系台账：5.BIZ一覧・6.ルール一覧・7.用語集・8.IF・CD・CF・A一覧・9.MV一覧・10.TC一覧・11.画面項目・MSG・12.課題・決策・CHK内部ID・13.文書ID台帳，各一览均含实施状态列。10.TC一覧 E 列（対応MV）是「9.MV一覧」対応TC数 COUNTIF 的集計键，漏填会静默计 0。
B10: STEP 6 | C10: 在「14.要件×機能行列」打○ | D10: 行=要件，列=機能。有对应关系的交叉格填「○」（下拉选择）。右侧「合計」「判定」自动计算。
B11: STEP 7 | C11: 在「15.機能×画面行列」打○ | D11: 行=機能，列=画面。逻辑同上。
B12: STEP 8 | C12: 看「16.サマリー」查漏 | D12: 缺口数量与覆盖率自动统计。目标：所有未割当数为 0。
B14: 判定规则
B15: ⚠ 未割当（要件→機能） | C15: 某个要件没有任何机能承接 → 这个需求做不出来，必须补机能或明确 Won't 并让客户签字。
B16: ⚠ 要件未紐付（機能） | C16: 某个机能追不回任何要件 → 典型的「镀金」或范围蔓延，要么追回要件，要么砍掉。
B17: ⚠ 画面未紐付（機能） | C17: 某个机能没有画面 → 可能是批处理/后台机能（合理），也可能是画面漏设计。
B18: ⚠ 未割当（画面） | C18: 某个画面没有任何机能支撑 → 孤儿画面，多半是漏了机能或该画面本不该存在。
B19: 多重割当 | C19: 一个要件对应多个机能、或机能跨多个画面，都是正常的。矩阵的价值恰恰是让多对多关系显式化。
B21: 使用注意
B22: ・扩充行数：本模板容量为 要件 60 行 / 機能 60 行 / 画面 80 行。如需扩充，插入行后把上一行的公式向下复制即可，行列表的 ID 引用会自动跟随。
B23: ・删除示例数据：2〜4 表与 14/15 行列中的灰色斜体行为示例（受注管理系统），直接整行清除开始使用。
B24: ・○ 的输入：交叉格已设置下拉，只能填「○」或留空，避免不同人写 ×／●／1 导致统计失效。
B25: ・颜色约定：蓝底=已建立对应；橙底=未割当（需要处置）；绿底=判定 OK。
A27: 【2026-09-01 台账整合版・更新说明（出典：requirement-definition-draft/interview-portfolio-id-registry.md・IDR-01 V1.1）】
A28: ・本ブックは chogeer 語料の実データを投入した作業版。元テンプレートの書式・式パターンを維持し、出典は各表 A2 注記の語料文書。
A29: ・容量拡張：要件一覧 50→60 行（REQ 38＋NFR 14＝52 行分）。14.要件×機能行列の合計行は 54→64 行へ移設し、3.機能一覧 H 列と 16.サマリーの参照範囲も追従更新済み。
A30: ・NFR 行の判定：非機能要件の引受主体は設計文書（BD-10）のため、対応機能 0 でも「⚠ 未割当」でなく「設計文書承接」と表示。2.要件一覧 I 列（I42:I55）と 14.行列 BK 列（BK42:BK55）の両方に変体式を適用済み。
A31: ・16.サマリー D5 は「⚠ 未割当」文字列件数を数える式に変更（NFR を欠落扱いしないため）。残る ⚠ は REQ-032（retention＝機能一覧外の運用機能）・REQ-035/036（不実施＝Won't）の 3 件で、いずれも意図済みの欠落。
A32: ・15.機能×画面行列で対応画面 0 の機能（F-03・F-15・F-20・F-25・F-30〜33）はバックグラウンド/システム機能または対象外（テンプレート A2 注記の正常系）。F-21 は S-04 の入口ボタンとして計上。D6 の 1 件は F-15（対象外・要件化外）による
A33: ・一览系シート 5〜13 が ID 台账の全系列を収容：BIZ（5）・RULE（6）・TERM（7）・IF/CD/CF/A（8）・MV（9）・TC（10）・S-xx-yy/MSG（11）・ISS/G/ADR/P0-n/CHK 内部（12）・文書 ID（13）。
A34: ・COUNTIF 集計キー：2.要件一覧 J 列（対応業務 ID）→5.BIZ一覧・10.TC一覧 E 列（対応MV）→9.MV一覧。集計はワイルドカード一致（※ID は完全形で記載）。
A35: ・条件付き書式（行ハイライト）は容量拡張行 54〜63 に適用外。NFR 行は ⚠ を出さない（設計文書承接表示）ためハイライト不在は実害なし。
A36: ・DV プルダウン語彙を語料の実値に拡張（種別にログイン/提示・優先度に Won't/—（対象外）・状態に設計承接）し、接尾辞付き自由文（例「未着手（P0-3 計画）」）をエラーにしないよう showErrorMessage=False に設定。
A37: 【2026-09-01 構成変更】①一览系 9 シートを 4.画面一覧 の直後に移動し 5〜13 に再採番（タブ色は 4.画面一覧 に一致）②行列 2 枚を 14/15 に再採番しサマリー直前に配置③サマリーは 16.サマリー に改名（1〜16 完整序列）④各一览に实施状态列を追加（语料の進捗と一致）⑤先頭に引用文档一览を追加⑥跨表式の参照名を全部追従更新。⑦2.要件一覧/3.機能一覧/4.画面一覧 にも正規化済み实施状态列（✅/🔵/⚪/⛔ 記号视图）を追加。
A38: 【2026-09-01 補全・更新说明】①步骤表を STEP 1〜8 に拡張：STEP 1 引用文档一览（IDR-01 対応）・STEP 5 一览系台账 5〜13（集計键提示：2.要件一覧 J 列→5.BIZ一覧・10.TC一覧 E 列→9.MV一覧）②使用注意を修正：容量 要件 60 行・行列番号 14/15
... A43: 【2026-09-03 回写反映】監査発見の文書遅延分を回写：REQ-018/024/029/030/031 部分実施（P0-3 SF 側 S-1〜S-3 実装〔11a7c78/907fe02/6b9d970〕）・F-20 部分実施・P0-2 工程行 C 列完了統一・G3 決定済反映。連動版数：RD-01 V1.2・BD-02 V2.1・DD-01 V1.1・PPT-01 V1.6・CHK-02 V1.7（D-4 実行・REQ-021 文案修正）

Sheet 2.要件一覧
A1: 要件一覧（機能要件一覧）
A2: 每行为一条要件。A 列的 ID 是后面所有文档的追溯源头，编号一经验证不再回收。灰色斜体行为示例数据，可整行删除。出典：RD-01（REQ 行）・RD-02（NFR 行）
A3: 要件 ID | B3: 要件名 / 概要 | C3: 分类 | D3: 来源（部门・访谈・法令） | E3: 优先级 | F3: 验收条件（可测量） | G3: 状态 | H3: 対応機能数 | I3: 判定 | J3: 対応業務 ID（出典 RD-01・追記列） | K3: 实施状态 | L3: 工程
A4: REQ-001 | B4: ユーザー登録：電話番号＋6桁認証コード＋氏名／メールで顧客アカウントを登録する | C4: 機能 | D4: 事業要件（予約受付のオンライン化） | E4: Must | F4: 電話番号＋認証コード＋氏名で登録が完了し、重複電話番号では登録が拒否されること（F-02） | G4: 実装済 | H4: =IF($A4="","",'14.要件×機能行列'!$BJ4) | I4: =IF($A4="","",IF($H4="","",IF($H4=0,"⚠ 未割当","OK"))) | J4: BIZ-01 | K4: ✅ 実装済 | L4: 既存（実装済）
A5: REQ-002 | B5: 認証ログイン：電話番号＋6桁認証コードでログインし、JWT（access/refresh/csrf）を HttpOnly Cookie で発行する | C5: 機能 | D5: 事業要件（アカウント認証） | E5: Must | F5: 正しい認証コードでログイン成功し HttpOnly Cookie が発行される。誤コードでは失敗すること（F-01） | G5: 実装済 | H5: =IF($A5="","",'14.要件×機能行列'!$BJ5) | I5: =IF($A5="","",IF($H5="","",IF($H5=0,"⚠ 未割当","OK"))) | J5: BIZ-02 | K5: ✅ 実装済 | L5: 既存（実装済）
A6: REQ-003 | B6: トークン更新・ログアウト・検証：401 時の自動更新、ログアウト時トークン無効化（Redis ブラックリスト） | C6: 機能 | D6: 事業要件（セッション維持） | E6: Must | F6: 更新・ログアウト・検証の各操作が成功し、ログアウト後のトークンは無効であること（F-03） | G6: 実装済 | H6: =IF($A6="","",'14.要件×機能行列'!$BJ6) | I6: =IF($A6="","",IF($H6="","",IF($H6=0,"⚠ 未割当","OK"))) | J6: BIZ-02 | K6: ✅ 実装済 | L6: 既存（実装済）
A7: REQ-004 | B7: サービスカタログ照会：稼働中サービスの一覧を閲覧する | C7: 機能 | D7: 事業要件（予約対象の選択） | E7: Must | F7: GET /v1/services で稼働中サービス一覧が返ること（F-04） | G7: 実装済 | H7: =IF($A7="","",'14.要件×機能行列'!$BJ7) | I7: =IF($A7="","",IF($H7="","",IF($H7=0,"⚠ 未割当","OK"))) | J7: BIZ-03 | K7: ✅ 実装済 | L7: 既存（実装済）
A8: REQ-005 | B8: 予約可能時間枠照会：指定日の空き時間枠を照会する（時間枠容量は 1） | C8: 機能 | D8: 事業要件（空き状況の提示） | E8: Must | F8: 指定日の予約済み時間枠が空き一覧に含まれないこと（F-05、RULE-06） | G8: 実装済 | H8: =IF($A8="","",'14.要件×機能行列'!$BJ8) | I8: =IF($A8="","",IF($H8="","",IF($H8=0,"⚠ 未割当","OK"))) | J8: BIZ-03 | K8: ✅ 実装済 | L8: 既存（実装済）
A9: REQ-006 | B9: 予約作成：サービス・時間枠を指定し予約（status=PENDING）を作成する | C9: 機能 | D9: 事業要件（予約受付） | E9: Must | F9: 作成成功時に Appointment 1 件が生成される。満席・重複・無効時間枠では拒否されること（F-06、RULE-05/06） | G9: 実装済 | H9: =IF($A9="","",'14.要件×機能行列'!$BJ9) | I9: =IF($A9="","",IF($H9="","",IF($H9=0,"⚠ 未割当","OK"))) | J9: BIZ-03 | K9: ✅ 実装済 | L9: 既存（実装済）
A10: REQ-007 | B10: 本人予約照会：自分の予約リスト・詳細を照会する（他人の予約は参照不可） | C10: 機能 | D10: 事業要件（予約確認） | E10: Must | F10: 顧客は自分の予約のみ取得でき、他者の予約 ID 指定では取得できないこと（F-07） | G10: 実装済 | H10: =IF($A10="","",'14.要件×機能行列'!$BJ10) | I10: =IF($A10="","",IF($H10="","",IF($H10=0,"⚠ 未割当","OK"))) | J10: BIZ-05 | K10: ✅ 実装済 | L10: 既存（実装済）
A11: REQ-008 | B11: 予約変更・キャンセル・削除：予約内容の変更、キャンセル（取消確認メール非同期送信）、ハード削除 | C11: 機能 | D11: 事業要件（予約の変更・取消） | E11: Must | F11: PENDING/CONFIRMED からの変更・取消が成功し、CANCELLED/COMPLETED からの取消は拒否されること（F-08、RULE-05/07） | G11: 実装済 | H11: =IF($A11="","",'14.要件×機能行列'!$BJ11) | I11: =IF($A11="","",IF($H11="","",IF($H11=0,"⚠ 未割当","OK"))) | J11: BIZ-04 | K11: ✅ 実装済 | L11: 既存（実装済）
A12: REQ-009 | B12: 通知：サイト内通知一覧・既読・未読数および WebSocket による通知配信 | C12: 機能 | D12: 事業要件（予約変更の通知） | E12: Could | F12: 通知一覧取得・既読化が成功し、WebSocket で通知が受信できること（F-09） | G12: 実装済 | H12: =IF($A12="","",'14.要件×機能行列'!$BJ12) | I12: =IF($A12="","",IF($H12="","",IF($H12=0,"⚠ 未割当","OK"))) | J12: BIZ-06 | K12: ✅ 実装済 | L12: 既存（実装済）
A13: REQ-010 | B13: 管理者予約管理：全量リスト・日次別・統計サマリによる予約管理 | C13: 機能 | D13: 事業要件（予約運用） | E13: Must | F13: ADMIN が全量・日次別・統計の各照会を取得できること。顧客ロールでは拒否されること（F-10） | G13: 実装済 | H13: =IF($A13="","",'14.要件×機能行列'!$BJ13) | I13: =IF($A13="","",IF($H13="","",IF($H13=0,"⚠ 未割当","OK"))) | J13: BIZ-07 | K13: ✅ 実装済 | L13: 既存（実装済）
A14: REQ-011 | B14: サービス管理：サービスの CRUD と稼働・停止 | C14: 機能 | D14: 事業要件（メニュー管理） | E14: Must | F14: ADMIN がサービス登録・変更・停止を行え、停止サービスが顧客一覧から消えること（F-11） | G14: 実装済 | H14: =IF($A14="","",'14.要件×機能行列'!$BJ14) | I14: =IF($A14="","",IF($H14="","",IF($H14=0,"⚠ 未割当","OK"))) | J14: BIZ-08 | K14: ✅ 実装済 | L14: 既存（実装済）
A15: REQ-012 | B15: 時間枠管理：時間枠の CRUD と稼働・停止 | C15: 機能 | D15: 事業要件（枠管理） | E15: Must | F15: ADMIN が時間枠を登録・停止でき、停止枠が空き照会から除外されること（F-13） | G15: 実装済 | H15: =IF($A15="","",'14.要件×機能行列'!$BJ15) | I15: =IF($A15="","",IF($H15="","",IF($H15=0,"⚠ 未割当","OK"))) | J15: BIZ-08 | K15: ✅ 実装済 | L15: 既存（実装済）
... A41: REQ-038 | B41: 動的 provisioning／deprovisioning（SalesforceUserLink・Contact/User 生成・提権降権）の不実施（P1 持ち越し） | C41: 運用 | D41: 範囲決定（P1 計画） | E41: Won't | F41: P0 では動的な外部ユーザー生成・権限変更が発生しないこと（事前設定 1 名のみ） | G41: 保留（P1） | H41: =IF($A41="","",'14.要件×機能行列'!$BJ41) | I41: =IF($A41="","",IF($H41="","",IF($H41=0,"⚠ 未割当","OK"))) | J41: BIZ-09, BIZ-10 | K41: ⚪ P1 保留 | L41: P1
A42: NFR-01 | B42: 性能：予約一覧・照会表示 | C42: 非機能 | D42: RD-02 非機能要件一覧 | E42: — | F42: 予約一覧・照会表示（S-03）が 3 秒以内に描画完了すること（デモデータ数十件・単一ユーザー・3 回平均） | G42: 設計承接（BD-10） | H42: =IF($A42="","",'14.要件×機能行列'!$BJ42) | I42: =IF($A42="","",IF($H42="","",IF($H42=0,"設計文書承接","OK"))) | K42: 設計承接（BD-10） | L42: —
A43: NFR-02 | B43: 性能：予約作成 API 応答 | C43: 非機能 | D43: RD-02 非機能要件一覧 | E43: — | F43: 予約作成 API 応答が 3 秒以内であること（時間枠競合リトライ発生時を除く） | G43: 設計承接（BD-10） | H43: =IF($A43="","",'14.要件×機能行列'!$BJ43) | I43: =IF($A43="","",IF($H43="","",IF($H43=0,"設計文書承接","OK"))) | K43: 設計承接（BD-10） | L43: —
A44: NFR-03 | B44: 性能：コマンド受付応答 | C44: 非機能 | D44: RD-02 非機能要件一覧 | E44: — | F44: コマンド受付応答（commandId／QUEUED 返却）が 2 秒以内であること。バックグラウンド完了時間は非同期のため目標値設定なし | G44: 設計承接（BD-10） | H44: =IF($A44="","",'14.要件×機能行列'!$BJ44) | I44: =IF($A44="","",IF($H44="","",IF($H44=0,"設計文書承接","OK"))) | K44: 設計承接（BD-10） | L44: —
A45: NFR-04 | B45: セキュリティ（認証）：A1・A3 | C45: 非機能 | D45: RD-02 非機能要件一覧 | E45: — | F45: ①A1：JWT（access/refresh/csrf）を HttpOnly Cookie で発行し 6 桁認証コードでログイン。②A3：Integration Guard が secret 鍵バージョン・audience・scope・時刻偏差を検証 | G45: 設計承接（BD-10） | H45: =IF($A45="","",'14.要件×機能行列'!$BJ45) | I45: =IF($A45="","",IF($H45="","",IF($H45=0,"設計文書承接","OK"))) | K45: 設計承接（BD-10） | L45: —
A46: NFR-05 | B46: セキュリティ（認可）：サーバ側最終裁定 | C46: 非機能 | D46: RD-02 非機能要件一覧 | E46: — | F46: ロール（CUSTOMER/ADMIN）ごとにサーバ側が最終裁定し、顧客 JWT による管理系 API 呼出は 403 となること | G46: 設計承接（BD-10） | H46: =IF($A46="","",'14.要件×機能行列'!$BJ46) | I46: =IF($A46="","",IF($H46="","",IF($H46=0,"設計文書承接","OK"))) | K46: 設計承接（BD-10） | L46: —
A47: NFR-06 | B47: セキュリティ（認可）：SF 行級 | C47: 非機能 | D47: RD-02 非機能要件一覧 | E47: — | F47: Booking__c／Booking_Command__c は External OWD=Private＋Sharing Set（Account 隔離）とし、外部ユーザーは自 Account のレコードのみ CRUD/FLS の範囲で操作できること | G47: 設計承接（BD-10） | H47: =IF($A47="","",'14.要件×機能行列'!$BJ47) | I47: =IF($A47="","",IF($H47="","",IF($H47=0,"設計文書承接","OK"))) | K47: 設計承接（BD-10） | L47: —
A48: NFR-07 | B48: セキュリティ（監査ログ）：連携トレース | C48: 非機能 | D48: RD-02 非機能要件一覧 | E48: — | F48: CorrelationId・LastError を Booking__c／Booking_Command__c 双方に、AttemptCount・HttpStatus・NextAttemptAt を Booking_Command__c に記録。Site ログインは LoginHistory で追跡可能なこと | G48: 設計承接（BD-10） | H48: =IF($A48="","",'14.要件×機能行列'!$BJ48) | I48: =IF($A48="","",IF($H48="","",IF($H48=0,"設計文書承接","OK"))) | K48: 設計承接（BD-10） | L48: —
A49: NFR-08 | B49: セキュリティ（暗号化・PII 排除） | C49: 非機能 | D49: RD-02 非機能要件一覧 | E49: — | F49: 全通信を HTTPS とする。JWT は HttpOnly Cookie。PII 5 項目（氏名・電話・メール・WeChat・備考）は投影ペイロード・Booking__c のいずれにも出現しないこと | G49: 設計承接（BD-10） | H49: =IF($A49="","",'14.要件×機能行列'!$BJ49) | I49: =IF($A49="","",IF($H49="","",IF($H49=0,"設計文書承接","OK"))) | K49: 設計承接（BD-10） | L49: —
A50: NFR-09 | B50: セキュリティ（脆弱性）：Apex カバレッジ | C50: 非機能 | D50: RD-02 非機能要件一覧 | E50: — | F50: Apex テストカバレッジ 75% 以上を維持し、P0 定義テスト（初回／重複／並行投影、旧バージョン、合法取消、409、503 Mock、権限拒否）が全件成功すること | G50: 設計承接（BD-10） | H50: =IF($A50="","",'14.要件×機能行列'!$BJ50) | I50: =IF($A50="","",IF($H50="","",IF($H50=0,"設計文書承接","OK"))) | K50: 設計承接（BD-10） | L50: —
A51: NFR-10 | B51: 可用性：デモ級（目標値なし） | C51: 非機能 | D51: RD-02 非機能要件一覧 | E51: — | F51: 単一構成・デモ級につき可用性率の数値目標を設定しない（RTO/RPO 不設定）。障害時は手動再起動（compose restart）で復旧すること | G51: 設計承接（BD-10） | H51: =IF($A51="","",'14.要件×機能行列'!$BJ51) | I51: =IF($A51="","",IF($H51="","",IF($H51=0,"設計文書承接","OK"))) | K51: 設計承接（BD-10） | L51: —
A52: NFR-11 | B52: 運用：retention 周期実行 | C52: 非機能 | D52: RD-02 非機能要件一覧 | E52: — | F52: retention（30 日ハードデリート）が周期実行されること。デモ期間中は月 1 回、削除ログ／件数を目視確認する | G52: 設計承接（BD-10） | H52: =IF($A52="","",'14.要件×機能行列'!$BJ52) | I52: =IF($A52="","",IF($H52="","",IF($H52=0,"設計文書承接","OK"))) | K52: 設計承接（BD-10） | L52: —
A53: NFR-12 | B53: 移行：行わない | C53: 非機能 | D53: RD-02 非機能要件一覧 | E53: — | F53: 既存システムからのデータ移行は行わない（新規構築）。移行検証は不要（対象外確認のみ） | G53: 設計承接（BD-10） | H53: =IF($A53="","",'14.要件×機能行列'!$BJ53) | I53: =IF($A53="","",IF($H53="","",IF($H53=0,"設計文書承接","OK"))) | K53: 設計承接（BD-10） | L53: —
... A55: NFR-14 | B55: 法令・互換性：PII・標準機能内 | C55: 非機能 | D55: RD-02 非機能要件一覧 | E55: — | F55: 個人情報を連携目的外に提供しない（投影ホワイトリスト運用で担保）。Salesforce 標準のセキュリティ機能（OWD・Sharing Set・CRUD/FLS）の範囲内で実装すること | G55: 設計承接（BD-10） | H55: =IF($A55="","",'14.要件×機能行列'!$BJ55) | I55: =IF($A55="","",IF($H55="","",IF($H55=0,"設計文書承接","OK"))) | K55: 設計承接（BD-10） | L55: —
H56: =IF($A56="","",'14.要件×機能行列'!$BJ56) | I56: =IF($A56="","",IF($H56="","",IF($H56=0,"⚠ 未割当","OK")))
H57: =IF($A57="","",'14.要件×機能行列'!$BJ57) | I57: =IF($A57="","",IF($H57="","",IF($H57=0,"⚠ 未割当","OK")))
H58: =IF($A58="","",'14.要件×機能行列'!$BJ58) | I58: =IF($A58="","",IF($H58="","",IF($H58=0,"⚠ 未割当","OK")))
H59: =IF($A59="","",'14.要件×機能行列'!$BJ59) | I59: =IF($A59="","",IF($H59="","",IF($H59=0,"⚠ 未割当","OK")))
H60: =IF($A60="","",'14.要件×機能行列'!$BJ60) | I60: =IF($A60="","",IF($H60="","",IF($H60=0,"⚠ 未割当","OK")))
H61: =IF($A61="","",'14.要件×機能行列'!$BJ61) | I61: =IF($A61="","",IF($H61="","",IF($H61=0,"⚠ 未割当","OK")))
H62: =IF($A62="","",'14.要件×機能行列'!$BJ62) | I62: =IF($A62="","",IF($H62="","",IF($H62=0,"⚠ 未割当","OK")))
H63: =IF($A63="","",'14.要件×機能行列'!$BJ63) | I63: =IF($A63="","",IF($H63="","",IF($H63=0,"⚠ 未割当","OK")))

Sheet 3.機能一覧
A1: 機能一覧（機能概要一覧）
A2: 机能按「业务目的」切分，不按画面切。H / I 列由行列自动统计，不要手改。灰色斜体行为示例数据。出典：BD-02 機能一覧
A3: 機能 ID | B3: 機能名 | C3: 概要（达成什么业务目的） | D3: 対応要件 ID | E3: 担当ロール | F3: 新規/改修/共通 | G3: 優先度 | H3: 対応要件数 | I3: 対応画面数 | J3: 判定 | K3: 实施状态 | L3: 工程
A4: F-01 | B4: 電話番号認証コードログイン | C4: 6 桁 SMS 認証コードでログインし、access/refresh/csrf を HttpOnly Cookie で発行する | D4: REQ-002 | E4: 顧客・管理者 | F4: 既存流用（共通認証） | G4: Must | H4: =IF($A4="","",'14.要件×機能行列'!B$64) | I4: =IF($A4="","",'15.機能×画面行列'!$CD4) | J4: =IF($A4="","",IF($H4=0,"⚠ 要件未紐付",IF($I4=0,"⚠ 画面未紐付","OK"))) | K4: ✅ 既存実装 | L4: 既存（実装済）
A5: F-02 | B5: ユーザー登録 | C5: 電話番号＋認証コード＋氏名／メールで顧客アカウントを登録（電話番号重複チェック付き） | D5: REQ-001 | E5: 顧客 | F5: 既存流用 | G5: Must | H5: =IF($A5="","",'14.要件×機能行列'!C$64) | I5: =IF($A5="","",'15.機能×画面行列'!$CD5) | J5: =IF($A5="","",IF($H5=0,"⚠ 要件未紐付",IF($I5=0,"⚠ 画面未紐付","OK"))) | K5: ✅ 既存実装 | L5: 既存（実装済）
A6: F-03 | B6: トークン更新・ログアウト・検証 | C6: 401 時の自動更新、ログアウト時にトークンを Redis ブラックリストへ登録、トークン有効性検証 | D6: REQ-003 | E6: 顧客・管理者 | F6: 既存流用（共通認証） | G6: Must | H6: =IF($A6="","",'14.要件×機能行列'!D$64) | I6: =IF($A6="","",'15.機能×画面行列'!$CD6) | J6: =IF($A6="","",IF($H6=0,"⚠ 要件未紐付",IF($I6=0,"⚠ 画面未紐付","OK"))) | K6: ✅ 既存実装 | L6: 既存（実装済）
A7: F-04 | B7: サービスカタログ照会 | C7: 稼働中サービスの一覧を閲覧 | D7: REQ-004 | E7: 顧客 | F7: 既存流用 | G7: Must | H7: =IF($A7="","",'14.要件×機能行列'!E$64) | I7: =IF($A7="","",'15.機能×画面行列'!$CD7) | J7: =IF($A7="","",IF($H7=0,"⚠ 要件未紐付",IF($I7=0,"⚠ 画面未紐付","OK"))) | K7: ✅ 既存実装 | L7: 既存（実装済）
A8: F-05 | B8: 予約可能時間枠照会 | C8: 指定日の空き時間枠を照会（時間枠容量は現状固定値 1） | D8: REQ-005 | E8: 顧客 | F8: 既存流用 | G8: Must | H8: =IF($A8="","",'14.要件×機能行列'!F$64) | I8: =IF($A8="","",'15.機能×画面行列'!$CD8) | J8: =IF($A8="","",IF($H8=0,"⚠ 要件未紐付",IF($I8=0,"⚠ 画面未紐付","OK"))) | K8: ✅ 既存実装 | L8: 既存（実装済）
A9: F-06 | B9: 予約作成 | C9: サービス・時間枠を検証し予約（status=PENDING）を作成 | D9: REQ-006 | E9: 顧客 | F9: 既存流用 | G9: Must | H9: =IF($A9="","",'14.要件×機能行列'!G$64) | I9: =IF($A9="","",'15.機能×画面行列'!$CD9) | J9: =IF($A9="","",IF($H9=0,"⚠ 要件未紐付",IF($I9=0,"⚠ 画面未紐付","OK"))) | K9: ✅ 既存実装 | L9: 既存（実装済）
A10: F-07 | B10: 本人予約照会 | C10: 自分の予約リスト・詳細を照会（非管理者はバックエンド側で本人レコードに絞り込み） | D10: REQ-007 | E10: 顧客 | F10: 既存流用 | G10: Must | H10: =IF($A10="","",'14.要件×機能行列'!H$64) | I10: =IF($A10="","",'15.機能×画面行列'!$CD10) | J10: =IF($A10="","",IF($H10=0,"⚠ 要件未紐付",IF($I10=0,"⚠ 画面未紐付","OK"))) | K10: ✅ 既存実装 | L10: 既存（実装済）
A11: F-08 | B11: 予約変更・キャンセル・削除 | C11: 状態遷移検証（RULE-05・RULE-07）のうえ変更・取消を実施。取消確認メールは非同期送信。DELETE は取消動作（status→CANCELLED・行保留） | D11: REQ-008 | E11: 顧客 | F11: 既存流用 | G11: Must | H11: =IF($A11="","",'14.要件×機能行列'!I$64) | I11: =IF($A11="","",'15.機能×画面行列'!$CD11) | J11: =IF($A11="","",IF($H11=0,"⚠ 要件未紐付",IF($I11=0,"⚠ 画面未紐付","OK"))) | K11: ✅ 既存実装 | L11: 既存（実装済）
A12: F-09 | B12: 通知 | C12: サイト内通知一覧・既読化・未読数＋WebSocket による通知配信 | D12: REQ-009 | E12: 顧客 | F12: 既存流用 | G12: Could | H12: =IF($A12="","",'14.要件×機能行列'!J$64) | I12: =IF($A12="","",'15.機能×画面行列'!$CD12) | J12: =IF($A12="","",IF($H12=0,"⚠ 要件未紐付",IF($I12=0,"⚠ 画面未紐付","OK"))) | K12: ✅ 既存実装 | L12: 既存（実装済）
A13: F-10 | B13: 管理コンソール（予約管理タブ） | C13: 全量リスト・日次別・統計サマリによる予約管理 | D13: REQ-010 | E13: 管理者 | F13: 既存流用 | G13: Must | H13: =IF($A13="","",'14.要件×機能行列'!K$64) | I13: =IF($A13="","",'15.機能×画面行列'!$CD13) | J13: =IF($A13="","",IF($H13=0,"⚠ 要件未紐付",IF($I13=0,"⚠ 画面未紐付","OK"))) | K13: ✅ 既存実装 | L13: 既存（実装済）
A14: F-11 | B14: サービス管理タブ | C14: サービス CRUD と稼働・停止 | D14: REQ-011 | E14: 管理者 | F14: 既存流用 | G14: Must | H14: =IF($A14="","",'14.要件×機能行列'!L$64) | I14: =IF($A14="","",'15.機能×画面行列'!$CD14) | J14: =IF($A14="","",IF($H14=0,"⚠ 要件未紐付",IF($I14=0,"⚠ 画面未紐付","OK"))) | K14: ✅ 既存実装 | L14: 既存（実装済）
A15: F-12 | B15: ユーザー管理タブ | C15: ユーザー作成・照会・統計、状態変更（セッション取消）、ロール変更（旧トークン拒否・guard 化済・DB セッション行対応は P1）、削除 | D15: REQ-013 | E15: 管理者 | F15: 既存流用 | G15: Must | H15: =IF($A15="","",'14.要件×機能行列'!M$64) | I15: =IF($A15="","",'15.機能×画面行列'!$CD15) | J15: =IF($A15="","",IF($H15=0,"⚠ 要件未紐付",IF($I15=0,"⚠ 画面未紐付","OK"))) | K15: ✅ 既存実装 | L15: 既存（実装済）
A16: F-13 | B16: 時間枠管理 | C16: 時間枠 CRUD と稼働・停止 | D16: REQ-012 | E16: 管理者 | F16: 既存流用 | G16: Must | H16: =IF($A16="","",'14.要件×機能行列'!N$64) | I16: =IF($A16="","",'15.機能×画面行列'!$CD16) | J16: =IF($A16="","",IF($H16=0,"⚠ 要件未紐付",IF($I16=0,"⚠ 画面未紐付","OK"))) | K16: ✅ 既存実装 | L16: 既存（実装済）
A17: F-14 | B17: アカウント状態提示 | C17: 無効化・降格ユーザーを提示ページへ誘導（?reason=ROLE_CHANGED_FROM_ADMIN） | D17: REQ-015 | E17: 顧客・管理者 | F17: 既存流用 | G17: Should | H17: =IF($A17="","",'14.要件×機能行列'!O$64) | I17: =IF($A17="","",'15.機能×画面行列'!$CD17) | J17: =IF($A17="","",IF($H17=0,"⚠ 要件未紐付",IF($I17=0,"⚠ 画面未紐付","OK"))) | K17: ✅ 既存実装 | L17: 既存（実装済）
A18: F-15 | B18: ファイルアップロード | C18: 単一・複数ファイル、アバター画像（本スライス対象外・要件化対象外） | D18: —（対象外） | E18: 顧客・管理者 | F18: 既存流用 | G18: — | H18: =IF($A18="","",'14.要件×機能行列'!P$64) | I18: =IF($A18="","",'15.機能×画面行列'!$CD18) | J18: =IF($A18="","",IF($H18=0,"⚠ 要件未紐付",IF($I18=0,"⚠ 画面未紐付","OK"))) | K18: —（対象外・要件化外） | L18: 既存（実装済・要件/画面未紐付）
A19: F-20 | B19: 予約投影 | C19: 予約正本（TERM-08）の変更（作成・変更・キャンセル全て）を Booking__c（TERM-09）へ冪等投影。External ID 定位＋version ゲート＋eventId 再送対応。PII 含まず | D19: REQ-018（主）・REQ-019/024/029/033 | E19: システム（Booking API → Apex） | F19: 新規（P0-3 計画） | G19: Must | H19: =IF($A19="","",'14.要件×機能行列'!Q$64) | I19: =IF($A19="","",'15.機能×画面行列'!$CD19) | J19: =IF($A19="","",IF($H19=0,"⚠ 要件未紐付",IF($I19=0,"⚠ 画面未紐付","OK"))) | K19: 🔵 部分実施（SF 側受入口済〔6b9d970〕・Booking 側残） | L19: P0-3
A20: F-21 | B20: 管理者入口遷移 | C20: Booking 管理コンソールに「Salesforce 管理ワークベンチ」ボタンを表示し、Site ログインページへ遷移（遷移＝SSO ではない） | D20: REQ-017（前提 REQ-026） | E20: 管理者 | F20: 新規（P0-4 計画） | G20: Must | H20: =IF($A20="","",'14.要件×機能行列'!R$64) | I20: =IF($A20="","",'15.機能×画面行列'!$CD20) | J20: =IF($A20="","",IF($H20=0,"⚠ 要件未紐付",IF($I20=0,"⚠ 画面未紐付","OK"))) | K20: 🔵 P0-4 計画 | L20: P0-4
A21: F-22 | B21: Site 独立ログイン | C21: 外部ユーザーが /02/login から Experience Site に独立ログイン（Booking の PW/JWT/Cookie は送信しない・RULE-18） | D21: REQ-016 | E21: 管理者（外部ユーザーとして） | F21: 既存（P0-1・ログイン部分検証済） | G21: Must | H21: =IF($A21="","",'14.要件×機能行列'!S$64) | I21: =IF($A21="","",'15.機能×画面行列'!$CD21) | J21: =IF($A21="","",IF($H21=0,"⚠ 要件未紐付",IF($I21=0,"⚠ 画面未紐付","OK"))) | K21: ✅ 検証済（P0-1・ログイン部分） | L21: P0-1（完了）/P0-4
A22: F-23 | B22: 投影リスト表示 | C22: Site 内 LWC で自 Account の予約投影を閲覧（行級限定・読取専用） | D22: REQ-020（＋REQ-030） | E22: 管理者（外部ユーザーとして） | F22: 新規（P0-4 計画） | G22: Must | H22: =IF($A22="","",'14.要件×機能行列'!T$64) | I22: =IF($A22="","",'15.機能×画面行列'!$CD22) | J22: =IF($A22="","",IF($H22=0,"⚠ 要件未紐付",IF($I22=0,"⚠ 画面未紐付","OK"))) | K22: 🔵 P0-4 計画 | L22: P0-4
A23: F-24 | B23: キャンセルコマンド受理 | C23: Site から CANCEL_BOOKING を送信し、Booking_Command__c を生成して commandId／QUEUED を即時返却。状態はポーリングで取得 | D23: REQ-021（＋REQ-030） | E23: 管理者（送信）＋システム（受付） | F23: 新規（P0-3/P0-4 計画） | G23: Must | H23: =IF($A23="","",'14.要件×機能行列'!U$64) | I23: =IF($A23="","",'15.機能×画面行列'!$CD23) | J23: =IF($A23="","",IF($H23=0,"⚠ 要件未紐付",IF($I23=0,"⚠ 画面未紐付","OK"))) | K23: 🔵 P0-3/P0-4 計画 | L23: P0-3/P0-4
A24: F-25 | B24: コマンドバックグラウンド実行 | C24: Queueable が Named Credential で Booking 統合端点を呼出。Integration Guard・静的マッピング・ADMIN/ACTIVE・状態・expectedVersion を検証し同一トランザクションで正本更新。409＝リトライせず・503/timeout＝限定リトライ | D24: REQ-022（主）・REQ-023/024/026/027/028/029/031 | E24: システム | F24: 新規（P0-3 計画） | G24: Must | H24: =IF($A24="","",'14.要件×機能行列'!V$64) | I24: =IF($A24="","",'15.機能×画面行列'!$CD24) | J24: =IF($A24="","",IF($H24=0,"⚠ 要件未紐付",IF($I24=0,"⚠ 画面未紐付","OK"))) | K24: 🔵 P0-3 計画 | L24: P0-3
A25: F-26 | B25: 結果書き戻し | C25: コマンド成功後、バージョンゲート付きで canonical result を Booking__c に書き戻す（incomingVersion が高い場合のみ） | D25: REQ-025（＋REQ-024） | E25: システム | F25: 新規（P0-3 計画） | G25: Must | H25: =IF($A25="","",'14.要件×機能行列'!W$64) | I25: =IF($A25="","",'15.機能×画面行列'!$CD25) | J25: =IF($A25="","",IF($H25=0,"⚠ 要件未紐付",IF($I25=0,"⚠ 画面未紐付","OK"))) | K25: 🔵 P0-3 計画 | L25: P0-3
A26: F-30 | B26: Site アクセス・メンバー管理 | C26: Network Live・メンバー 4 件・SelfReg=false の維持確認 | D26: REQ-034（不実施確認対象） | E26: 管理者（外部ユーザー） | F26: 既存（P0-1） | G26: Won't | H26: =IF($A26="","",'14.要件×機能行列'!X$64) | I26: =IF($A26="","",'15.機能×画面行列'!$CD26) | J26: =IF($A26="","",IF($H26=0,"⚠ 要件未紐付",IF($I26=0,"⚠ 画面未紐付","OK"))) | K26: ✅ 既存（P0-1・REQ-034 確認対象） | L26: P0-1（完了）
A27: F-31 | B27: 外部ユーザーライフサイクル（静的部分） | C27: 事前設定 1 名の外部ユーザーで運用（動的部分は P1 保留） | D27: REQ-038（動的部分 P1） | E27: 管理者 | F27: 既存（静的 1 名）＋⚪ P1 | G27: Won't | H27: =IF($A27="","",'14.要件×機能行列'!Y$64) | I27: =IF($A27="","",'15.機能×画面行列'!$CD27) | J27: =IF($A27="","",IF($H27=0,"⚠ 要件未紐付",IF($I27=0,"⚠ 画面未紐付","OK"))) | K27: ✅ 静的 1 名（動的 ⚪ P1） | L27: 既存/P1
A28: F-32 | B28: オブジェクト権限マトリクス | C28: Booking__c／Booking_Command__c の外部ユーザー最小 CRUD/FLS・Sharing Set 行級・External OWD=Private | D28: REQ-030 | E28: システム（権限設定） | F28: 新規（P0-2 契約凍結） | G28: Must | H28: =IF($A28="","",'14.要件×機能行列'!Z$64) | I28: =IF($A28="","",'15.機能×画面行列'!$CD28) | J28: =IF($A28="","",IF($H28=0,"⚠ 要件未紐付",IF($I28=0,"⚠ 画面未紐付","OK"))) | K28: ✅ 実施済（2026-09-02・S-3/S-4） | L28: P0-2
A29: F-33 | B29: 信頼性配信・対合・告警 | C29: Outbox/Worker・DLQ・周期対合・指標告警（P1・本件スコープ外。P0 は直接呼出＋有限リトライ＋手動 Retry） | D29: REQ-037（本件では対応しない） | E29: システム | F29: ⚪ P1 | G29: Won't | H29: =IF($A29="","",'14.要件×機能行列'!AA$64) | I29: =IF($A29="","",'15.機能×画面行列'!$CD29) | J29: =IF($A29="","",IF($H29=0,"⚠ 要件未紐付",IF($I29=0,"⚠ 画面未紐付","OK"))) | K29: ⚪ P1（本件スコープ外） | L29: P1
H30: =IF($A30="","",'14.要件×機能行列'!AB$64) | I30: =IF($A30="","",'15.機能×画面行列'!$CD30) | J30: =IF($A30="","",IF($H30=0,"⚠ 要件未紐付",IF($I30=0,"⚠ 画面未紐付","OK")))
H31: =IF($A31="","",'14.要件×機能行列'!AC$64) | I31: =IF($A31="","",'15.機能×画面行列'!$CD31) | J31: =IF($A31="","",IF($H31=0,"⚠ 要件未紐付",IF($I31=0,"⚠ 画面未紐付","OK")))
H32: =IF($A32="","",'14.要件×機能行列'!AD$64) | I32: =IF($A32="","",'15.機能×画面行列'!$CD32) | J32: =IF($A32="","",IF($H32=0,"⚠ 要件未紐付",IF($I32=0,"⚠ 画面未紐付","OK")))
H33: =IF($A33="","",'14.要件×機能行列'!AE$64) | I33: =IF($A33="","",'15.機能×画面行列'!$CD33) | J33: =IF($A33="","",IF($H33=0,"⚠ 要件未紐付",IF($I33=0,"⚠ 画面未紐付","OK")))
H34: =IF($A34="","",'14.要件×機能行列'!AF$64) | I34: =IF($A34="","",'15.機能×画面行列'!$CD34) | J34: =IF($A34="","",IF($H34=0,"⚠ 要件未紐付",IF($I34=0,"⚠ 画面未紐付","OK")))
H35: =IF($A35="","",'14.要件×機能行列'!AG$64) | I35: =IF($A35="","",'15.機能×画面行列'!$CD35) | J35: =IF($A35="","",IF($H35=0,"⚠ 要件未紐付",IF($I35=0,"⚠ 画面未紐付","OK")))
H36: =IF($A36="","",'14.要件×機能行列'!AH$64) | I36: =IF($A36="","",'15.機能×画面行列'!$CD36) | J36: =IF($A36="","",IF($H36=0,"⚠ 要件未紐付",IF($I36=0,"⚠ 画面未紐付","OK")))
H37: =IF($A37="","",'14.要件×機能行列'!AI$64) | I37: =IF($A37="","",'15.機能×画面行列'!$CD37) | J37: =IF($A37="","",IF($H37=0,"⚠ 要件未紐付",IF($I37=0,"⚠ 画面未紐付","OK")))
H38: =IF($A38="","",'14.要件×機能行列'!AJ$64) | I38: =IF($A38="","",'15.機能×画面行列'!$CD38) | J38: =IF($A38="","",IF($H38=0,"⚠ 要件未紐付",IF($I38=0,"⚠ 画面未紐付","OK")))
H39: =IF($A39="","",'14.要件×機能行列'!AK$64) | I39: =IF($A39="","",'15.機能×画面行列'!$CD39) | J39: =IF($A39="","",IF($H39=0,"⚠ 要件未紐付",IF($I39=0,"⚠ 画面未紐付","OK")))
H40: =IF($A40="","",'14.要件×機能行列'!AL$64) | I40: =IF($A40="","",'15.機能×画面行列'!$CD40) | J40: =IF($A40="","",IF($H40=0,"⚠ 要件未紐付",IF($I40=0,"⚠ 画面未紐付","OK")))
...

Sheet 4.画面一覧
A1: 画面一覧
A2: 弹窗、确认页、错误页也要各给一个 ID，不要并入父画面。G 列由行列自动统计。灰色斜体行为示例数据。出典：BD-04 画面一覧
A3: 画面 ID | B3: 画面名 | C3: 概要 | D3: 種別 | E3: 対象ロール | F3: 新規/改修 | G3: 対応機能数 | H3: 判定 | I3: 实施状态 | J3: 工程
A4: S-01 | B4: ログイン | C4: 電話番号＋6 桁認証コードでログインする | D4: ログイン | E4: 未認証 | F4: 既存 | G4: =IF($A4="","",'15.機能×画面行列'!B$64) | H4: =IF($A4="","",IF($G4="","",IF($G4=0,"⚠ 未割当","OK"))) | I4: ✅ 既存実装 | J4: 既存（実装済）
A5: S-02 | B5: 登録 | C5: 電話番号＋認証コード＋氏名／メールでアカウント登録 | D5: 登録 | E5: 未認証 | F5: 既存 | G5: =IF($A5="","",'15.機能×画面行列'!C$64) | H5: =IF($A5="","",IF($G5="","",IF($G5=0,"⚠ 未割当","OK"))) | I5: ✅ 既存実装 | J5: 既存（実装済）
A6: S-03 | B6: 予約画面 | C6: サービス・時間枠の選択、予約作成・変更・取消、本人予約リスト（単一ページ） | D6: ダッシュボード | E6: 顧客（CUSTOMER）専用 | F6: 既存 | G6: =IF($A6="","",'15.機能×画面行列'!D$64) | H6: =IF($A6="","",IF($G6="","",IF($G6=0,"⚠ 未割当","OK"))) | I6: ✅ 既存実装 | J6: 既存（実装済）
A7: S-04 | B7: 管理コンソール | C7: 予約管理・サービス管理・ユーザー管理の 3 タブ（🔵 P0-4 入口ボタン追加予定） | D7: ダッシュボード | E7: 管理者（ADMIN） | F7: 既存 | G7: =IF($A7="","",'15.機能×画面行列'!E$64) | H7: =IF($A7="","",IF($G7="","",IF($G7=0,"⚠ 未割当","OK"))) | I7: ✅ 既存実装 | J7: 既存/P0-4（入口ボタン追加）
A8: S-05 | B8: アカウント状態提示 | C8: 無効化・降格の理由を提示する例外経路画面 | D8: 提示 | E8: 全ロール | F8: 既存 | G8: =IF($A8="","",'15.機能×画面行列'!F$64) | H8: =IF($A8="","",IF($G8="","",IF($G8=0,"⚠ 未割当","OK"))) | I8: ✅ 既存実装 | J8: 既存（実装済）
A9: S-10 | B9: Site ログイン | C9: 外部ユーザー認証情報による独立ログイン（✅ MV-03 検証済み・ログイン部分） | D9: ログイン | E9: 外部ユーザー（TERM-07） | F9: 既存（P0-1） | G9: =IF($A9="","",'15.機能×画面行列'!G$64) | H9: =IF($A9="","",IF($G9="","",IF($G9=0,"⚠ 未割当","OK"))) | I9: ✅ 既存（P0-1・ログイン ✅） | J9: P0-1（完了）
A10: S-11 | B10: 予約投影リスト | C10: 自 Account の投影（読取専用一覧）＋取消ボタンとコマンド状態ポーリング | D10: 一覧 | E10: 管理者（外部ユーザー） | F10: 新規（🔵 P0-4 計画） | G10: =IF($A10="","",'15.機能×画面行列'!H$64) | H10: =IF($A10="","",IF($G10="","",IF($G10=0,"⚠ 未割当","OK"))) | I10: 🔵 P0-4 計画（未実装） | J10: P0-4（新設）
G11: =IF($A11="","",'15.機能×画面行列'!I$64) | H11: =IF($A11="","",IF($G11="","",IF($G11=0,"⚠ 未割当","OK")))
G12: =IF($A12="","",'15.機能×画面行列'!J$64) | H12: =IF($A12="","",IF($G12="","",IF($G12=0,"⚠ 未割当","OK")))
G13: =IF($A13="","",'15.機能×画面行列'!K$64) | H13: =IF($A13="","",IF($G13="","",IF($G13=0,"⚠ 未割当","OK")))
G14: =IF($A14="","",'15.機能×画面行列'!L$64) | H14: =IF($A14="","",IF($G14="","",IF($G14=0,"⚠ 未割当","OK")))
G15: =IF($A15="","",'15.機能×画面行列'!M$64) | H15: =IF($A15="","",IF($G15="","",IF($G15=0,"⚠ 未割当","OK")))
G16: =IF($A16="","",'15.機能×画面行列'!N$64) | H16: =IF($A16="","",IF($G16="","",IF($G16=0,"⚠ 未割当","OK")))
G17: =IF($A17="","",'15.機能×画面行列'!O$64) | H17: =IF($A17="","",IF($G17="","",IF($G17=0,"⚠ 未割当","OK")))
G18: =IF($A18="","",'15.機能×画面行列'!P$64) | H18: =IF($A18="","",IF($G18="","",IF($G18=0,"⚠ 未割当","OK")))
G19: =IF($A19="","",'15.機能×画面行列'!Q$64) | H19: =IF($A19="","",IF($G19="","",IF($G19=0,"⚠ 未割当","OK")))
G20: =IF($A20="","",'15.機能×画面行列'!R$64) | H20: =IF($A20="","",IF($G20="","",IF($G20=0,"⚠ 未割当","OK")))
G21: =IF($A21="","",'15.機能×画面行列'!S$64) | H21: =IF($A21="","",IF($G21="","",IF($G21=0,"⚠ 未割当","OK")))
G22: =IF($A22="","",'15.機能×画面行列'!T$64) | H22: =IF($A22="","",IF($G22="","",IF($G22=0,"⚠ 未割当","OK")))
G23: =IF($A23="","",'15.機能×画面行列'!U$64) | H23: =IF($A23="","",IF($G23="","",IF($G23=0,"⚠ 未割当","OK")))
G24: =IF($A24="","",'15.機能×画面行列'!V$64) | H24: =IF($A24="","",IF($G24="","",IF($G24=0,"⚠ 未割当","OK")))
G25: =IF($A25="","",'15.機能×画面行列'!W$64) | H25: =IF($A25="","",IF($G25="","",IF($G25=0,"⚠ 未割当","OK")))
G26: =IF($A26="","",'15.機能×画面行列'!X$64) | H26: =IF($A26="","",IF($G26="","",IF($G26=0,"⚠ 未割当","OK")))
G27: =IF($A27="","",'15.機能×画面行列'!Y$64) | H27: =IF($A27="","",IF($G27="","",IF($G27=0,"⚠ 未割当","OK")))
G28: =IF($A28="","",'15.機能×画面行列'!Z$64) | H28: =IF($A28="","",IF($G28="","",IF($G28=0,"⚠ 未割当","OK")))
G29: =IF($A29="","",'15.機能×画面行列'!AA$64) | H29: =IF($A29="","",IF($G29="","",IF($G29=0,"⚠ 未割当","OK")))
G30: =IF($A30="","",'15.機能×画面行列'!AB$64) | H30: =IF($A30="","",IF($G30="","",IF($G30=0,"⚠ 未割当","OK")))
G31: =IF($A31="","",'15.機能×画面行列'!AC$64) | H31: =IF($A31="","",IF($G31="","",IF($G31=0,"⚠ 未割当","OK")))
G32: =IF($A32="","",'15.機能×画面行列'!AD$64) | H32: =IF($A32="","",IF($G32="","",IF($G32=0,"⚠ 未割当","OK")))
G33: =IF($A33="","",'15.機能×画面行列'!AE$64) | H33: =IF($A33="","",IF($G33="","",IF($G33=0,"⚠ 未割当","OK")))
G34: =IF($A34="","",'15.機能×画面行列'!AF$64) | H34: =IF($A34="","",IF($G34="","",IF($G34=0,"⚠ 未割当","OK")))
G35: =IF($A35="","",'15.機能×画面行列'!AG$64) | H35: =IF($A35="","",IF($G35="","",IF($G35=0,"⚠ 未割当","OK")))
G36: =IF($A36="","",'15.機能×画面行列'!AH$64) | H36: =IF($A36="","",IF($G36="","",IF($G36=0,"⚠ 未割当","OK")))
G37: =IF($A37="","",'15.機能×画面行列'!AI$64) | H37: =IF($A37="","",IF($G37="","",IF($G37=0,"⚠ 未割当","OK")))
G38: =IF($A38="","",'15.機能×画面行列'!AJ$64) | H38: =IF($A38="","",IF($G38="","",IF($G38=0,"⚠ 未割当","OK")))
G39: =IF($A39="","",'15.機能×画面行列'!AK$64) | H39: =IF($A39="","",IF($G39="","",IF($G39=0,"⚠ 未割当","OK")))
G40: =IF($A40="","",'15.機能×画面行列'!AL$64) | H40: =IF($A40="","",IF($G40="","",IF($G40=0,"⚠ 未割当","OK")))
...

Sheet 5.BIZ一覧
A1: 業務一覧（RD-03 出典・ID 台账 §4.1）
A2: 対応要件数は 2.要件一覧 J 列（対応業務 ID）からの COUNTIF 集計。業務名・関連要件 ID は RD-03 §2 の照録。
A3: 業務ID | B3: 業務名・概要 | C3: 担当ロール | D3: 関連要件 ID（RD-03 照録） | E3: 対応要件数（式） | F3: 業務フロー図 | G3: 实施状态 | H3: 工程
A4: BIZ-01 | B4: ユーザー登録 | C4: 顧客（未認証） | D4: REQ-001 | E4: =IF($A4="","",COUNTIF('2.要件一覧'!$J$4:$J$63,"*"&$A4&"*")) | F4: 図1・2 | G4: ✅ 既存実装 | H4: 既存（実装済）
A5: BIZ-02 | B5: ログイン・ログアウト | C5: 顧客・管理者 | D5: REQ-002, REQ-003, REQ-014 | E5: =IF($A5="","",COUNTIF('2.要件一覧'!$J$4:$J$63,"*"&$A5&"*")) | F5: 図1・2 | G5: ✅ 既存実装 | H5: 既存（実装済）
A6: BIZ-03 | B6: 予約作成 | C6: 顧客 | D6: REQ-004, REQ-005, REQ-006 | E6: =IF($A6="","",COUNTIF('2.要件一覧'!$J$4:$J$63,"*"&$A6&"*")) | F6: 図1・2 | G6: ✅ 既存実装 | H6: 既存（実装済）
A7: BIZ-04 | B7: 予約変更・キャンセル・削除 | C7: 顧客 | D7: REQ-008 | E7: =IF($A7="","",COUNTIF('2.要件一覧'!$J$4:$J$63,"*"&$A7&"*")) | F7: 図1・2 | G7: ✅ 既存実装 | H7: 既存（実装済）
A8: BIZ-05 | B8: 予約照会（本人） | C8: 顧客 | D8: REQ-007 | E8: =IF($A8="","",COUNTIF('2.要件一覧'!$J$4:$J$63,"*"&$A8&"*")) | F8: 図1・2 | G8: ✅ 既存実装 | H8: 既存（実装済）
A9: BIZ-06 | B9: 通知確認 | C9: 顧客 | D9: REQ-009 | E9: =IF($A9="","",COUNTIF('2.要件一覧'!$J$4:$J$63,"*"&$A9&"*")) | F9: 図1・2 | G9: ✅ 既存実装 | H9: 既存（実装済）
A10: BIZ-07 | B10: 予約管理（管理者） | C10: 管理者 | D10: REQ-010, REQ-014 | E10: =IF($A10="","",COUNTIF('2.要件一覧'!$J$4:$J$63,"*"&$A10&"*")) | F10: 図3 | G10: ✅ 既存実装 | H10: 既存（実装済）
A11: BIZ-08 | B11: サービス・時間枠管理 | C11: 管理者 | D11: REQ-011, REQ-012, REQ-014 | E11: =IF($A11="","",COUNTIF('2.要件一覧'!$J$4:$J$63,"*"&$A11&"*")) | F11: 図3 | G11: ✅ 既存実装 | H11: 既存（実装済）
A12: BIZ-09 | B12: ユーザー管理 | C12: 管理者 | D12: REQ-013, REQ-014, REQ-015, REQ-035, REQ-038 | E12: =IF($A12="","",COUNTIF('2.要件一覧'!$J$4:$J$63,"*"&$A12&"*")) | F12: 図3 | G12: ✅ 既存実装 | H12: 既存（実装済）
A13: BIZ-10 | B13: Salesforce 管理ワークベンチ入口利用 | C13: 管理者 | D13: REQ-017, REQ-026, REQ-038 | E13: =IF($A13="","",COUNTIF('2.要件一覧'!$J$4:$J$63,"*"&$A13&"*")) | F13: 図4 | G13: 未着手（P0-4 計画） | H13: P0-4
A14: BIZ-11 | B14: Experience Site 独立ログイン | C14: 管理者（外部ユーザーとして） | D14: REQ-016, REQ-034 | E14: =IF($A14="","",COUNTIF('2.要件一覧'!$J$4:$J$63,"*"&$A14&"*")) | F14: 図4 | G14: ✅ 検証済（ログイン部分・P0-1） | H14: P0-1（完了）/P0-4
A15: BIZ-12 | B15: 予約投影（正本変更の冪等投影） | C15: システム（Booking API → Apex） | D15: REQ-018, REQ-019, REQ-024, REQ-025, REQ-029, REQ-031, REQ-033, REQ-036, REQ-037 | E15: =IF($A15="","",COUNTIF('2.要件一覧'!$J$4:$J$63,"*"&$A15&"*")) | F15: 図5 | G15: 未着手（P0-3 計画） | H15: P0-3
... A19: BIZ-16 | B19: 予約データ保持・消去（30 日ハードデリート） | C19: システム＋管理者（月次確認） | D19: REQ-032, REQ-033 | E19: =IF($A19="","",COUNTIF('2.要件一覧'!$J$4:$J$63,"*"&$A19&"*")) | F19: 図7 | G19: ✅ 既存実装（月次確認は手動） | H19: 既存（実装済）

Sheet 6.ルール一覧
A1: 業務ルール一覧（RD-05 出典）
A2: ルール内容は RD-05 §2 の要約（原文は同書参照）。主検証アンカーは RD-05 §3 の対応表による（RULE-06 は §3 未記載のため —）。
A3: ルールID | B3: 対応業務ID | C3: ルール内容（要約） | D3: 適用タイミング | E3: 主検証アンカー（RD-05 §3） | F3: 实施状态 | G3: 工程
A4: RULE-01 | B4: BIZ-12 | C4: 投影受信時、incomingVersion <= CurrentVersion__c は受理を拒否し Booking__c を更新しない | D4: 投影 REST 受信時 | E4: MV-05・MV-06 | F4: 未着手（P0-3 計画） | G4: P0-3
A5: RULE-02 | B5: BIZ-14 | C5: expectedVersion != 正本 version の場合は 409＋currentVersion＋correlationId を返し正本を更新しない | D5: Booking 統合端点の業務判定時 | E5: MV-09 | F5: 未着手（P0-3 計画） | G5: P0-3
A6: RULE-03 | B6: BIZ-14 | C6: 同一 commandId の再到達では初回保存済み結果を返し、副作用を再実行しない | D6: Booking 統合端点受信時 | E6: MV-08（重複口径） | F6: 未着手（P0-3 計画） | G6: P0-3
A7: RULE-04 | B7: BIZ-12 | C7: 同一 eventId の投影再送では初回の受理結果を返し、レコードを追加更新しない（LastEventId__c 判定） | D7: 投影 REST 受信時 | E7: MV-05・MV-06 | F7: 未着手（P0-3 計画） | G7: P0-3
A8: RULE-05 | B8: BIZ-04, BIZ-14 | C8: 合法遷移は PENDING→CONFIRMED／PENDING→CANCELLED／CONFIRMED→CANCELLED／CONFIRMED→COMPLETED のみ。終状態への遷移は不可 | D8: 予約更新・取消・コマンド適用時 | E8: 実装済 UT＋MV-09 | F8: ✅ 既存実装（現行仕様） | G8: 既存（実装済）
A9: RULE-06 | B9: BIZ-03 | C9: 予約作成は対象時間枠が稼働中かつ予約済みでない（実効容量=1）場合のみ受理。競合は直列化＋限定リトライ | D9: 予約作成時 | E9: —（RD-05 §3 未記載） | F9: ✅ 既存実装（現行仕様） | G9: 既存（実装済）
A10: RULE-07 | B10: BIZ-04, BIZ-14 | C10: 取消は PENDING/CONFIRMED のみ。CANCELLED 宛の新 commandId・COMPLETED 宛は 409 | D10: 取消実行時 | E10: MV-09 | F10: ✅ 既存実装（現行仕様） | G10: 既存（実装済）
A11: RULE-08 | B11: BIZ-12 | C11: 正本変更は同一トランザクションで正本更新＋version+1＋syncStatus=PENDING。version は単調増加 | D11: 正本変更トランザクション内 | E11: MV-04 | F11: 未着手（P0-3 計画） | G11: P0-3
A12: RULE-09 | B12: BIZ-14, BIZ-15 | C12: 409＝業務競合（自動リトライせず CONFLICT）。503/429/timeout＝一時的障害（attemptCount+1・限定回数リトライ） | D12: Queueable の応答処理時 | E12: MV-10 | F12: 未着手（P0-3 計画） | G12: P0-3
A13: RULE-10 | B13: BIZ-15 | C13: リトライ上限到達で FAILED とし、手動 Retry は原 commandId で実行（新 commandId を発行しない） | D13: リトライ上限到達時・手動 Retry 時 | E13: MV-10 | F13: 未着手（P0-3 計画） | G13: P0-3
A14: RULE-11 | B14: BIZ-12 | C14: 投影ホワイトリストは 9 項目のみ。PII 5 項目はペイロード・Booking__c のいずれにも含めない | D14: 投影ペイロード生成時・項目設計時 | E14: MV-04 併せて確認（PII） | F14: ✅ 凍結済（2026-09-01・CHK-01 C-2） | G14: P0-2
... A21: RULE-18 | B21: BIZ-11 | C21: Booking の機密（PW・JWT・Cookie・認証コード）は Salesforce に送信しない。両ログイン状態は完全に独立 | D21: 入口遷移時・Site ログイン時 | E21: MV-03（検証済・ログイン部分） | F21: ✅ 検証済（ログイン部分・P0-1） | G21: P0-1（完了）/P0-4

Sheet 7.用語集
A1: 用語集（RD-06 出典）
A2: 用語名は日本語/英語表記（中国語参考列は RD-06 原表参照）。🔵＝P0 計画（未実装）。
A3: 用語ID | B3: 用語名（日本語 / 英語） | C3: 物理名候補 | D3: 備考 | E3: 实施状态 | F3: 工程
A4: TERM-01 | B4: 予約 / Appointment | C4: Appointment（status: PENDING|CONFIRMED|CANCELLED|COMPLETED） | E4: ✅ 既存 | F4: 既存（実装済）
A5: TERM-02 | B5: 予約枠 / TimeSlot | C5: TimeSlot | E5: ✅ 既存 | F5: 既存（実装済）
A6: TERM-03 | B6: サービス / Service | C6: Service | E6: ✅ 既存 | F6: 既存（実装済）
A7: TERM-04 | B7: サービスカテゴリ / ServiceCategory | C7: ServiceCategory | E7: ✅ 既存 | F7: 既存（実装済）
A8: TERM-05 | B8: 顧客 / CUSTOMER | C8: User.userType = CUSTOMER | E8: ✅ 既存 | F8: 既存（実装済）
A9: TERM-06 | B9: 管理者 / ADMIN | C9: User.userType = ADMIN | E9: ✅ 既存 | F9: 既存（実装済）
A10: TERM-07 | B10: 外部ユーザー / External User | C10: Salesforce User（Chatter Communities External User） | E10: ✅ 既存 | F10: P0-1（完了）/P0-4
A11: TERM-08 | B11: 正本 / Canonical Record | C11: Appointment | E11: ✅ 既存 | F11: 既存（実装済）
A12: TERM-09 | B12: 投影 / Projection | C12: Booking__c | D12: 🔵 | E12: 🔵 一部実装（Booking__c 設置済・投影実行 P0-3） | F12: P0-3
A13: TERM-10 | B13: バージョン / Version | C13: Appointment.version・Booking__c.CurrentVersion__c・Booking_Command__c.ExpectedVersion__c / ResultVersion__c | D13: 🔵 | E13: 🔵 一部実装（schema 設置済・ゲート実行 P0-3） | F13: P0-3
A14: TERM-11 | B14: コマンド / Booking Command | C14: Booking_Command__c | D14: 🔵 | E14: 🔵 一部実装（Booking_Command__c 設置済・実行 P0-3/P0-4） | F14: P0-3/P0-4
A15: TERM-12 | B15: コマンドID / commandId | C15: Booking_Command__c.CommandId__c | D15: 🔵 | E15: 🔵 未実装（P0 計画） | F15: P0-3/P0-4
A16: TERM-13 | B16: 冪等性 / Idempotency | C16: （設計原則・個別物理名なし） | E16: 設計原則（P0-2/P0-3 で適用） | F16: P0-2/P0-3
A17: TERM-14 | B17: 外部ID / External ID | C17: Booking__c.BookingExternalId__c | D17: ✅ 二択決定済（uuid `id`・CHK-01 C-1・2026-09-01） | E17: ✅ 実装済（2026-09-02・BookingExternalId__c） | F17: P0-2
A18: TERM-15 | B18: 予約番号 / appointmentNumber | C18: Appointment.appointmentNumber・Booking__c.AppointmentNumber__c | D18: 🔵 | E18: 🔵 未実装（P0 計画） | F18: P0-3
A19: TERM-16 | B19: 同期状態 / syncStatus | C19: Appointment.syncStatus・Booking__c.SyncStatus__c | D19: 🔵 | E19: 🔵 一部実装（schema 設置済・同期実行 P0-3） | F19: P0-3
A20: TERM-17 | B20: 相関ID / correlationId | C20: Booking__c.CorrelationId__c・Booking_Command__c.CorrelationId__c | D20: 🔵 | E20: 🔵 未実装（P0 計画） | F20: P0-3
A21: TERM-18 | B21: イベントID / eventId | C21: Booking__c.LastEventId__c | D21: 🔵 | E21: 🔵 未実装（P0 計画） | F21: P0-3
A22: TERM-19 | B22: Experience Cloud サイト / Experience Cloud Site | C22: （Site 名 my call center・/02・Live） | E22: ✅ 構築済（P0-1） | F22: P0-1（完了）
A23: TERM-20 | B23: 外部クライアントアプリケーション（ECA・OAuth 2.0 JWT ベアラー） | C23: ECA Booking_Integration_API（P0-3 で構成済み・2026-09-02 Connected App より移行） | D23: 🔵 | E23: 🔵 未実装（P0 計画） | F23: P0-3
A24: TERM-21 | B24: Named Credential | C24: Booking_Integration_API（計画名） | D24: 🔵 | E24: 🔵 未実装（P0 計画） | F24: P0-3
A25: TERM-22 | B25: Queueable / Queueable（Apex 非同期処理） | C25: BookingCommandQueueable（計画クラス名） | D25: 🔵 | E25: 🔵 未実装（P0 計画） | F25: P0-3
A26: TERM-23 | B26: Integration Guard | C26: ガード実装（クラス名は P0-3 で確定） | D26: 🔵 | E26: 🔵 未実装（P0 計画） | F26: P0-3
A27: TERM-24 | B27: 投影入口 / BookingProjectionRest | C27: BookingProjectionRest（計画クラス名） | D27: 🔵 | E27: 🔵 未実装（P0 計画） | F27: P0-3
A28: TERM-25 | B28: Site コントローラ / BookingSiteController | C28: BookingSiteController（計画クラス名） | D28: 🔵 | E28: 🔵 未実装（P0 計画） | F28: P0-3
A29: TERM-26 | B29: 静的操作者マッピング | C29: マッピングテーブル（P0-3 で確定・P1 計画名 SalesforceUserLink） | D29: 🔵 | E29: 🔵 未実装（P0 計画） | F29: P0-3
A30: TERM-27 | B30: 業務競合 / Business Conflict (409) | C30: HTTP 409 | E30: ✅ 既存 | F30: P0-3
A31: TERM-28 | B31: 一時的障害 / Temporary Failure (503/timeout) | C31: HTTP 503 | E31: ✅ 既存 | F31: P0-3
A32: TERM-29 | B32: 個人情報 / PII | C32: Appointment.customerName/customerPhone/customerEmail/customerWechat/notes（投影外） | E32: ✅ 既存 | F32: P0-3
A33: TERM-30 | B33: データ保持 / Retention | C33: retention モジュール | E33: ✅ 既存 | F33: 既存（実装済）
A34: TERM-31 | B34: 認証コード / Verification Code | C34: （Redis 保存・検証用データ） | E34: ✅ 既存 | F34: 既存（実装済）
A35: TERM-32 | B35: 共有設定 / Sharing Set（＋External OWD） | C35: Sharing Set 設定＋外部 OWD=Private | D35: 🔵 | E35: 🔵 一部実装（P0-2：Sharing Set/OWD 済・P0-4 検証残） | F35: P0-2/P0-4
A36: TERM-33 | B36: LWC / Lightning Web コンポーネント | C36: LWC バンドル（P0-4 で命名） | D36: 🔵 | E36: 🔵 未実装（P0 計画） | F36: P0-4
A37: TERM-34 | B37: Outbox（P1 計画） | C37: Outbox（P1 計画・物理名未確定） | D37: 🔵 | E37: ⚪ P1 計画（未実装） | F37: P1
A38: TERM-35 | B38: コマンド状態 / Command Status | C38: Booking_Command__c.Status__c（QUEUED|RUNNING|SUCCEEDED|CONFLICT|FAILED） | D38: 🔵 | E38: 🔵 未実装（P0 計画） | F38: P0-3/P0-4

Sheet 8.IF・CD・CF・A一覧
A1: I/F・コード・共通機能・認証境界一覧
A2: 出典：BD-09 §2（IF）／BD-08 §2（CD）／BD-11 §2（CF）／BD-01 §4（A1〜A4）。ID 台账 §2.3 の各系列を一括収容。
A4: ■ I/F 一覧（IF・2 件）
A5: I/F ID | B5: 名称 | C5: 方向 | D5: 対応機能 | E5: 認証 | F5: 实施状态 | G5: 工程
A6: IF-01 | B6: 予約投影 | C6: Booking → Salesforce | D6: F-20 | E6: OAuth 2.0 JWT Bearer（ECA・A2） | F6: 未着手（P0-3 計画） | G6: P0-3
A7: IF-02 | B7: 予約キャンセルコマンド | C7: Salesforce → Booking | D7: F-25 | E7: Named Credential（Bearer secret）＋Integration Guard（A3） | F7: 未着手（P0-3 計画） | G7: P0-3
A9: ■ コード一覧（CD・11 件）
A10: コードID | B10: 名称・物理名 | C10: 値域と各値の意味（要約） | D10: 分類 | E10: 備考 | F10: 实施状态 | G10: 工程
A11: CD-01 | B11: ユーザー種別・UserType | C11: CUSTOMER／ADMIN | D11: 業務コード | F11: ✅ 既存実装（Prisma enum） | G11: 既存（実装済）
A12: CD-02 | B12: ユーザー状態・UserStatus | C12: ACTIVE／INACTIVE／BLOCKED | D12: 業務コード | F12: ✅ 既存実装（Prisma enum） | G12: 既存（実装済）
A13: CD-03 | B13: 予約状態・AppointmentStatus | C13: PENDING／CONFIRMED／CANCELLED（終状態）／COMPLETED（終状態） | D13: 業務コード | E13: IF-01 §3.6・IF-02 409 判定 | F13: ✅ 既存実装（Prisma enum） | G13: 既存（実装済）
A14: CD-04 | B14: 通知種別・NotificationType | C14: SMS／EMAIL／WECHAT／PUSH | D14: 業務コード | F14: ✅ 既存実装（Prisma enum） | G14: 既存（実装済）
A15: CD-05 | B15: 通知状態・NotificationStatus | C15: PENDING／SENT／FAILED／CANCELLED | D15: 業務コード | F15: ✅ 既存実装（Prisma enum） | G15: 既存（実装済）
A16: CD-06 | B16: 同期状態・syncStatus | C16: PENDING／SYNCED／ERROR | D16: システム内部コード | E16: ✅ P0-2 実装（schema migration） | F16: ✅ 実装済（2026-09-02・migration） | G16: P0-2
A17: CD-07 | B17: 投影状態・Booking__c.Status__c | C17: CD-03 と同一 canonical 値 | D17: 業務コード（投影複製値） | E17: ✅ P0-2 実装（SF 側） | F17: ✅ 実装済（2026-09-02・SF 側） | G17: P0-2
A18: CD-08 | B18: コマンド状態・Booking_Command__c.Status__c | C18: QUEUED→RUNNING→SUCCEEDED／CONFLICT／FAILED（終状態） | D18: システム内部コード | E18: ✅ P0-2 実装（SF 側） | F18: ✅ 実装済（2026-09-02・SF 側） | G18: P0-2
A19: CD-09 | B19: 設定型別・SettingType | C19: STRING／NUMBER／BOOLEAN／JSON | D19: システム内部コード | E19: 対応端点は現状不可用 | F19: ✅ 既存実装（Prisma enum） | G19: 既存（実装済）
A20: CD-10 | B20: 設定分類・SettingCategory | C20: GENERAL／SECURITY／BUSINESS／SYSTEM | D20: システム内部コード | F20: ✅ 既存実装（Prisma enum） | G20: 既存（実装済）
A21: CD-11 | B21: 予約操作・AppointmentAction | C21: CREATE／UPDATE／CONFIRM／CANCEL／COMPLETE | D21: システム内部コード | E21: 参照先なし・既知課題 | F21: ✅ 既存実装（Prisma enum） | G21: 既存（実装済）
A23: ■ 共通機能一覧（CF・7 件）
A24: 共通機能ID | B24: 名称 | C24: 対応 NFR | D24: 状態 | E24: 備考 | F24: 实施状态 | G24: 工程
A25: CF-01 | B25: 認証・認可 | C25: NFR-04・NFR-05 | D25: ✅（連携側拡張 🔵） | E25: NestJS Guard・APP_GUARD | F25: ✅ 既存実装 | G25: 既存（実装済）
A26: CF-02 | B26: トークン無効化 | C26: NFR-04 | D26: ✅ | E26: Redis ブラックリスト | F26: ✅ 既存実装 | G26: 既存（実装済）
A27: CF-03 | B27: エラーレスポンス | C27: NFR-05・NFR-09 | D27: ✅ Booking／🔵 連携 | E27: 409/503/401/403 の区分共有 | F27: ✅ 既存実装 | G27: 既存（実装済）
A28: CF-04 | B28: ログ出力 | C28: NFR-07 | D28: ✅ | E28: ActivityLog／SystemLog | F28: ✅ 既存実装 | G28: 既存（実装済）
A29: CF-05 | B29: 採番（eventId・correlationId・commandId） | C29: NFR-07 | D29: 🔵 P0-2/P0-3 計画 | E29: 一意性のみ・順序性なし | F29: 🔵 P0-2/P0-3 計画 | G29: P0-2/P0-3
A30: CF-06 | B30: 日付・タイムゾーン処理 | C30: NFR-07（間接） | D30: ✅（規約化 🔵） | E30: フロント JST・バックエンド UTC | F30: ✅ 既存実装 | G30: 既存（実装済）
A31: CF-07 | B31: 保持・削除 | C31: NFR-11・NFR-14 | D31: ✅ | E31: retention：CronJob＋deleteMany | F31: ✅ 既存実装 | G31: 既存（実装済）
A33: ■ 認証境界（A・4 件）
A34: ID | B34: 経路 | C34: 認証手段 | D34: 対応 I/F | E34: 備考 | F34: 实施状态 | G34: 工程
A35: A1 | B35: 顧客／管理者 → Booking API | C35: JWT（HttpOnly Cookie）＋6 桁認証コード・DB ロール参照 | D35: — | E35: ✅ 実装済 | F35: ✅ 実装済 | G35: 既存（実装済）
A36: A2 | B36: Booking サービス → Salesforce | C36: OAuth 2.0 JWT Bearer（ECA・2026-09-02 Connected App より移行） | D36: IF-01 | E36: 🔵 P0-3 | F36: 🔵 P0-3 計画 | G36: P0-3
A37: A3 | B37: Salesforce Queueable → Booking API | C37: Named Credential＋Integration Guard | D37: IF-02 | E37: 🔵 P0-3 | F37: 🔵 P0-3 計画 | G37: P0-3
A38: A4 | B38: 管理者 → Experience Site | C38: 外部ユーザー認証情報の独立ログイン（遷移＝SSO ではない） | D38: — | E38: 遷移 🔵 P0-4／ログイン ✅ MV-03 | F38: 遷移 🔵 P0-4／ログイン ✅ | G38: 既存/P0-4

Sheet 9.MV一覧
A1: 最小検証マトリクス一覧（experience-site-mvp-validation.md §4 出典）
A2: 対応 TC 数は 10.TC一覧 E 列（対応MV）からの COUNTIF 集計。MV-01〜03 はブラウザ検証のため自動化 TC を持たない（式は 0 を返す・テンプレートの仕様上の正常系）。出典：experience-site-mvp-validation.md §4
A3: MV ID | B3: 内容 | C3: 主対応 F | D3: 方式 | E3: 対応 TC 数（式） | F3: 対応 TC・備考 | G3: 实施状态 | H3: 工程
A4: MV-01 | B4: 普通用户边界：顧客に Salesforce 入口が見えず、管理 API も 403 | C4: Booking 既存機能 | D4: 真实链路（ブラウザ） | E4: =IF($A4="","",COUNTIF('10.TC一覧'!$E$4:$E$31,"*"&$A4&"*")) | F4: 自動化 TC なし（NFR-05 後半の実測） | G4: 未実施（P0-4 ブラウザ検証） | H4: P0-4/P0-5（証跡）
A5: MV-02 | B5: 管理员入口：入口ボタンで Experience Site へ遷移 | C5: F-21 | D5: 真实链路（P0-4） | E5: =IF($A5="","",COUNTIF('10.TC一覧'!$E$4:$E$31,"*"&$A5&"*")) | F5: 自動化 TC なし（RULE-16 の描画判定） | G5: 未実施（P0-4） | H5: P0-4
A6: MV-03 | B6: 独立登录：外部ユーザーが Site に独立ログイン | C6: F-22 | D6: 真实链路 | E6: =IF($A6="","",COUNTIF('10.TC一覧'!$E$4:$E$31,"*"&$A6&"*")) | F6: ✅ 検証済（ログイン部分・2026-08-31） | G6: ✅ 検証済（ログイン部分・2026-08-31） | H6: P0-1（完了）/P0-4
A7: MV-04 | B7: 首次投影：予約作成で Booking__c 1 件・External ID と version 正しい | C7: F-20 | D7: 真实链路＋自動 | E7: =IF($A7="","",COUNTIF('10.TC一覧'!$E$4:$E$31,"*"&$A7&"*")) | F7: TC-01・TC-06 | G7: 未実施（P0-3 自動化） | H7: P0-3
A8: MV-05 | B8: 投影幂等/乱序：同一イベント再送で増えず・旧 version は拒否 | C8: F-20 | D8: 自動化 | E8: =IF($A8="","",COUNTIF('10.TC一覧'!$E$4:$E$31,"*"&$A8&"*")) | F8: TC-02・TC-03・TC-04 | G8: 未実施（P0-3 自動化） | H8: P0-3
A9: MV-06 | B9: 并发首次投影：同一 External ID の並行初回で 1 件のみ | C9: F-20 | D9: 自動化 | E9: =IF($A9="","",COUNTIF('10.TC一覧'!$E$4:$E$31,"*"&$A9&"*")) | F9: TC-05 | G9: 未実施（P0-3 自動化） | H9: P0-3
A10: MV-07 | B10: Site 权限：授权レコード・項目のみ閲覧可能 | C10: F-23 | D10: 真实链路（P0-4・F-23 完了時） | E10: =IF($A10="","",COUNTIF('10.TC一覧'!$E$4:$E$31,"*"&$A10&"*")) | F10: TC-12 | G10: 未実施（P0-4・F-23 完了時） | H10: P0-4
A11: MV-08 | B11: 合法取消：commandId 返却→正本 CANCELLED→結果回写 | C11: F-24・F-25・F-26 | D11: 真实链路＋自動 | E11: =IF($A11="","",COUNTIF('10.TC一覧'!$E$4:$E$31,"*"&$A11&"*")) | F11: TC-07・TC-20 | G11: 未実施（P0-3） | H11: P0-3
A12: MV-09 | B12: 业务冲突：旧 expectedVersion・完了予約取消は 409 | C12: F-25 | D12: 自動化 | E12: =IF($A12="","",COUNTIF('10.TC一覧'!$E$4:$E$31,"*"&$A12&"*")) | F12: TC-08・TC-23 | G12: 未実施（P0-3） | H12: P0-3
A13: MV-10 | B13: 暂时性失败：前 2 回 503・第 3 回成功＋継続失敗 | C13: F-25 | D13: 自動化 | E13: =IF($A13="","",COUNTIF('10.TC一覧'!$E$4:$E$31,"*"&$A13&"*")) | F13: TC-09・TC-10 | G13: 未実施（P0-3） | H13: P0-3
A14: MV-11 | B14: 服务端认证：誤 audience/scope/key は 401/403・状態不変 | C14: F-25 | D14: 自動化 | E14: =IF($A14="","",COUNTIF('10.TC一覧'!$E$4:$E$31,"*"&$A14&"*")) | F14: TC-11・TC-17・TC-18 | G14: 未実施（P0-3） | H14: P0-3

Sheet 10.TC一覧
A1: 単体テストケース一覧（DD-04 §3/§4 出典）
A2: 対応F・対応MV は DD-04 備考列（対応機能 ID）の照録。E 列は 9.MV一覧の COUNTIF 集計キー（MV 束縛なしの TC は —）。
A3: TC ID | B3: 対象モジュール・メソッド | C3: 観点 | D3: 対応F | E3: 対応MV | F3: RULE・REQ 等出典（要点） | G3: 实施状态 | H3: 工程
A4: TC-01 | B4: BookingProjectionRest.receiveProjection | C4: 正常（初回投影成功） | D4: F-20 | E4: MV-04 | F4: RULE-01/04・IF-01 | G4: ✅ 実施済（2026-09-02・S-3/T-1・BookingProjectionRestTest 15/15 PASS） | H4: P0-3
A5: TC-02 | B5: BookingProjectionRest.receiveProjection | C5: 冪等（同一 eventId 再送） | D5: F-20 | E5: MV-05 | F5: RULE-04 | G5: ✅ 実施済（2026-09-02・S-3/T-1・BookingProjectionRestTest 15/15 PASS） | H5: P0-3
A6: TC-03 | B6: BookingProjectionRest.receiveProjection | C6: 異常（旧 version 拒否） | D6: F-20 | E6: MV-05 | F6: RULE-01・REQ-024 | G6: ✅ 実施済（2026-09-02・S-3/T-1・BookingProjectionRestTest 15/15 PASS） | H6: P0-3
A7: TC-04 | B7: BookingProjectionRest.receiveProjection | C7: 境界（同 version・別 eventId は拒否） | D7: F-20 | E7: MV-05 | F7: RULE-01/04 | G7: ✅ 実施済（2026-09-02・S-3/T-1・BookingProjectionRestTest 15/15 PASS） | H7: P0-3
A8: TC-05 | B8: BookingProjectionRest.receiveProjection | C8: 並行（並行初回投影） | D8: F-20 | E8: MV-06 | F8: BD-03 §3.6 FOR UPDATE | G8: ✅ 実施済（2026-09-02・S-3/T-1・BookingProjectionRestTest 15/15 PASS） | H8: P0-3
A9: TC-06 | B9: BookingProjectionRest.receiveProjection | C9: 異常（PII 非含有） | D9: F-20 | E9: MV-04 | F9: RULE-11・REQ-019・NFR-09 | G9: ✅ 実施済（2026-09-02・S-3/T-1・BookingProjectionRestTest 15/15 PASS） | H9: P0-3
A10: TC-07 | B10: BookingCommandQueueable.execute | C10: 正常（合法取消成功） | D10: F-25/F-26 | E10: MV-08 | F10: RULE-14・REQ-025 | G10: 未実施（P0-3 計画） | H10: P0-3
A11: TC-08 | B11: BookingCommandQueueable.execute | C11: 異常（409 業務競合） | D11: F-25 | E11: MV-09 | F11: RULE-02/09/14 | G11: 未実施（P0-3 計画） | H11: P0-3
A12: TC-09 | B12: BookingCommandQueueable.execute | C12: 異常（503 一時障害・成功回復） | D12: F-25 | E12: MV-10 | F12: RULE-09 | G12: 未実施（P0-3 計画） | H12: P0-3
A13: TC-10 | B13: BookingCommandQueueable.execute | C13: 異常（継続失敗→FAILED） | D13: F-25 | E13: MV-10 | F13: RULE-10・REQ-028 | G13: 未実施（P0-3 計画） | H13: P0-3
A14: TC-11 | B14: BookingCommandQueueable.execute | C14: 異常（認証 NG 401/403） | D14: F-25 | E14: MV-11 | F14: RULE-14 注記・REQ-029 | G14: 未実施（P0-3 計画） | H14: P0-3
... A31: TC-28 | B31: 投影送信サービス.projectBooking | C31: 異常（投影失敗） | D31: F-20 | E31: — | F31: BD-09 §3.8・syncStatus=ERROR | G31: 未実施（P0-3 計画） | H31: P0-3

Sheet 11.画面項目・MSG
A1: 画面項目（S-xx-yy）・エラーメッセージ（MSG）一覧
A2: 出典：BD-05 §3（screen-items.md）。MSG の新規採番は BD-05 のみ（単点採番宣言・screen-items.md:14）。
A4: ■ 画面項目 ID（S-xx-yy・14 件：S-10-01〜04・S-11-01〜10）
A5: 項目ID | B5: 表示ラベル | C5: 物理名 | D5: 参照先 | E5: エラーメッセージID | F5: 備考 | G5: 实施状态 | H5: 工程
A6: S-10-01 | B6: ユーザー名 | C6: Username | D6: Salesforce User（TERM-07） | E6: なし（標準動作） | F6: 実態ベース記載 | G6: ✅ 既存（P0-1 構築済） | H6: P0-1（完了）
A7: S-10-02 | B7: パスワード | C7: Password | D7: Salesforce User | E7: なし（標準動作） | G7: ✅ 既存（P0-1 構築済） | H7: P0-1（完了）
A8: S-10-03 | B8: ログイン | C8: （ボタン） | D8: — | E8: なし | G8: ✅ 既存（P0-1 構築済） | H8: P0-1（完了）
A9: S-10-04 | B9: パスワードを忘れた場合 | C9: （リンク） | D9: — | E9: なし | G9: ✅ 既存（P0-1 構築済） | H9: P0-1（完了）
A10: S-11-01 | B10: 予約番号 | C10: AppointmentNumber__c | D10: BD-07 §3 | E10: — | F10: 🔵 P0-4 計画 | G10: 🔵 P0-4 計画（未実装） | H10: P0-4
A11: S-11-02 | B11: 予約日付 | C11: AppointmentDate__c | D11: BD-07 §3 | E11: — | G11: 🔵 P0-4 計画（未実装） | H11: P0-4
A12: S-11-03 | B12: 時間枠 | C12: TimeSlot__c | D12: BD-07 §3 | E12: — | G12: 🔵 P0-4 計画（未実装） | H12: P0-4
A13: S-11-04 | B13: サービス名 | C13: ServiceName__c | D13: BD-07 §3 | E13: — | G13: 🔵 P0-4 計画（未実装） | H13: P0-4
A14: S-11-05 | B14: 状態 | C14: Status__c | D14: CD-03/CD-07 | E14: — | F14: canonical 値 | G14: 🔵 P0-4 計画（未実装） | H14: P0-4
A15: S-11-06 | B15: キャンセル | C15: （ボタン） | D15: F-24・RULE-05/07 | E15: MSG-03・MSG-04 | F15: 行級範囲内のみ操作可 | G15: 🔵 P0-4 計画（未実装） | H15: P0-4
A16: S-11-07 | B16: 処理状態 | C16: Booking_Command__c.Status__c | D16: CD-08・F-24 | E16: MSG-05・MSG-06 | F16: ポーリング表示 | G16: 🔵 P0-4 計画（未実装） | H16: P0-4
A17: S-11-08 | B17: 再読み込み | C17: （ボタン） | D17: F-23 | E17: MSG-02 | G17: 🔵 P0-4 計画（未実装） | H17: P0-4
A18: S-11-09 | B18: （内部）現行バージョン | C18: CurrentVersion__c | D18: BD-07 §3・TERM-10 | E18: — | F18: 非表示・expectedVersion に利用 | G18: 🔵 P0-4 計画（未実装） | H18: P0-4
A19: S-11-10 | B19: （内部）外部ID | C19: BookingExternalId__c | D19: BD-07 §3・TERM-14 | E19: — | F19: 非表示・定位キー | G19: 🔵 P0-4 計画（未実装） | H19: P0-4
A21: ■ エラーメッセージ ID（MSG・6 件・全部 S-11）
A22: メッセージID | B22: メッセージ文面（設計値） | C22: 表示条件 | D22: 対象画面 | E22: 備考 | G22: 实施状态 | H22: 工程
A23: MSG-01 | B23: 表示できる予約データがありません | C23: 自 Account の投影が 0 件のとき | D23: S-11 | G23: 🔵 P0-4 計画（設計値） | H23: P0-4（文言確定）
A24: MSG-02 | B24: データの取得に失敗しました。再読み込みしてください | C24: 投影照会・状態照会の通信エラー | D24: S-11 | G24: 🔵 P0-4 計画（設計値） | H24: P0-4（文言確定）
A25: MSG-03 | B25: この操作は許可されていません | C25: 権限不足・行級範囲外の操作時 | D25: S-11 | G25: 🔵 P0-4 計画（設計値） | H25: P0-4（文言確定）
A26: MSG-04 | B26: この予約はキャンセルできません | C26: CANCELLED／COMPLETED 投影への取消操作時 | D26: S-11 | G26: 🔵 P0-4 計画（設計値） | H26: P0-4（文言確定）
A27: MSG-05 | B27: キャンセル処理が完了しませんでした（状態：{status}）。詳細は管理者に確認してください | C27: ポーリング結果が CONFLICT／FAILED のとき | D27: S-11 | G27: 🔵 P0-4 計画（設計値） | H27: P0-4（文言確定）
A28: MSG-06 | B28: キャンセルを受け付けました（受付番号：{commandId}）。状態が更新され次第表示されます | C28: コマンド受理（commandId／QUEUED 返却）直後 | D28: S-11 | G28: 🔵 P0-4 計画（設計値） | H28: P0-4（文言確定）

Sheet 12.課題・決策・CHK内部ID
A1: 課題（ISS）・決策（G/ADR）・CHK-01 内部 ID
A2: 出典：RD-08（ISS）／interview-portfolio-tech-decisions.md §G・ADR（G/ADR）／CHK-01（内部 ID）。ISS は RD-08 外ゼロ参照の孤児系列（ID 台账 §5.3）。
A4: ■ 課題一覧（ISS・8 件）
A5: 課題ID | B5: 課題内容（要約） | C5: 影響度 | D5: 対応要件ID | E5: 備考 | F5: 实施状态 | G5: 工程
A6: ISS-01 | B6: システム間の情報分断：確認のたびに Booking へ別ログイン＋目視照合 | C6: 高 | D6: REQ-016, REQ-017, REQ-018, REQ-020 | F6: 対応計画済・未着手（P0-2〜P0-4） | G6: P0-2〜P0-4
A7: ISS-02 | B7: 対応の滞留：取消が Booking 画面操作のみで SF 側から働きかけ不可 | C7: 中 | D7: REQ-021, REQ-022, REQ-025 | F7: 対応計画済・未着手（P0-2〜P0-4） | G7: P0-2〜P0-4
A8: ISS-03 | B8: 証跡・追跡性の欠如：相関 ID・エラー記録が存在しない | C8: 中 | D8: REQ-027, REQ-031 | F8: 部分対応（監査フィールド設置済〔P0-2 S-1/S-2〕・記録実装は P0-3 残） | G8: P0-2〜P0-4
A9: ISS-04 | B9: 個人情報の管理リスク：PII 統制方針が未定義 | C9: 高 | D9: REQ-019, REQ-030 | F9: 部分対応（方針凍結済〔RULE-11・CHK-01 C-2・2026-09-01〕） | G9: P0-2〜P0-4
A10: ISS-05 | B10: データ権威の不明瞭化リスク：正本が不明瞭になり二重管理 | C10: 中 | D10: REQ-018, REQ-024, REQ-025, REQ-036 | F10: 対応計画済・未着手（P0-2〜P0-4） | G10: P0-2〜P0-4
A11: ISS-06 | B11: 権限越境リスク：操作者特定の仕組みが未定義 | C11: 高 | D11: REQ-014, REQ-026, REQ-029, REQ-030 | F11: 部分対応（設計確定〔CHK-02 C-3〕＋行級制御設置済〔P0-2 S-3/S-4〕・runtime 実装は P0-3 残） | G11: P0-2〜P0-4
A12: ISS-07 | B12: 障害復旧が暫定的：Outbox/Worker 未導入・人手依存 | C12: 低〜中 | D12: REQ-027, REQ-028（対応）／REQ-037（P1） | F12: 対応計画済・未着手（P0-3 計画〔REQ-027/028・S-4/B-7 未実装〕・残り P1） | G12: P0＋P1
A13: ISS-08 | B13: 利用者ライフサイクル運用の非自動：手作業（事前設定 1 名） | C13: 低 | D13: REQ-038（P1） | F13: 未対応（P1） | G13: P1
A15: ■ G 決策寄存器（tech-decisions §G・7 件）
A16: G 番号 | B16: 内容 | C16: 状態 | D16: 引用分布 | E16: 備考 | F16: 实施状态 | G16: 工程
A17: G1 | B17: —（語料無引用・無定義） | C17: 未使用 | D17: — | F17: —（未使用） | G17: —
A18: G2 | B18: —（語料無引用・無定義） | C18: 未使用 | D18: — | F18: —（未使用） | G18: —
A19: G3 | B19: Named Credential 目標 URL 選定（dev compose vs booking-deploy） | C19: 未決・P0-3 NC 設定前 | D19: 引用 7 件（寄存器に file:line 全清单） | E19: RD-01 §4 未決 3 と同源 | F19: ✅ 決定済（2026-09-02・CHK-02 C-1＝booking-deploy 公網 HTTPS） | G19: P0-3
A20: G4 | B20: —（語料無引用・無定義） | C20: 未使用 | D20: — | E20: RD-04 の mermaid ノード名 PG4 とは別物 | F20: —（未使用） | G20: —
A21: G5 | B21: —（語料無引用・無定義） | C21: 未使用 | D21: — | F21: —（未使用） | G21: —
A22: G6 | B22: —（語料無引用・無定義） | C22: 未使用 | D22: — | F22: —（未使用） | G22: —
A23: G7 | B23: 投影記録保持方針：①投影は正本クリーンアップ対象外 ②遅延コマンドは 404/409 判定 | C23: 方针已定・決定記録成文済み（2026-09-01・p0-2/interview-portfolio-req033-decision-record.md・CHK-01 C-3 [x]） | D23: 引用 15 件（寄存器に file:line 全清单） | E23: REQ-033・RULE-15 例外欄と整合 | F23: ✅ 決定記録成文済み（2026-09-01） | G23: P0-2
A25: ■ ADR（tech-decisions・2 件） | F25: 实施状态 | G25: 工程
A26: ADR-1 | B26: 投影/命令リンクは Apex 三文献（BookingProjectionRest／BookingCommandQueueable／BookingSiteController）を維持。Flow 代替は評価のうえ否決 | E26: tech-decisions §ADR-1 | F26: ✅ 決定済（2026-08-31） | G26: —
A27: ADR-2 | B27: P0 は Trigger なしを維持。バージョン防御は validation rule PRIORVALUE。P1 で 2 条件（CDC 防環・動的投影）を再評価 | E27: tech-decisions §ADR-2 | F27: ✅ 決定済（2026-08-31） | G27: —
A29: ■ 工程 ID（P0-n・ID 台账 §2.5・PPT-01 出典）
A30: 工程 ID | B30: 名称 | C30: 状態 | D30: ゲート | E30: 備考 | F30: 实施状态 | G30: 工程
A31: P0-0 | B31: 公開リスク止血（README） | C31: ✅ 完了 | D31: 措施完了 | E31: PR #4 合并 | F31: ✅ 完了
A32: P0-1 | B32: Org/Site 前置条件 | C32: ✅ 閉鎖 | D32: Site 到達・ログイン成功（MV-03） | E32: 権限マトリクス凍結は P0-2 へ让渡 | F32: ✅ 完了
A33: P0-2 | B33: データとコマンド契約凍結 | C33: ✅ 完了（2026-09-02・G-3 確定） | D33: CHK-01 §7 G-1〜G-3（双方独立実装可能） | E33: 本ブックの母体資料 | F33: ✅ 完了（2026-09-02・G-3 確定）
A34: P0-3 | B34: サーバ縦断ループ | C34: 🔵 進行中（SF 側 S-1〜S-3 済〔11a7c78/907fe02/6b9d970〕・S-4/S-5/B 系 残） | D34: MV-04/05/06・08〜11 自動化テスト合格 | E34: BookingProjectionRest 等 Apex 三文献＋Booking 統合端点 | F34: 🔵 進行中（SF 側 S-1〜S-3 済・S-4/S-5/T-2〜T-5 残）
A35: P0-4 | B35: Site UI（LWC） | C35: ⬜ 未着手 | D35: MV-01〜03・07〜08 ブラウザ検証可 | E35: S-11 独自 LWC・F-21 入口ボタン | F35: ⬜ 未着手
A36: P0-5 | B36: 証跡パッケージ | C36: ⬜ 未着手 | D36: GO 判定（mvp-validation §8） | E36: MV-01〜11 全証跡 | F36: ⬜ 未着手
A37: P1 | B37: Outbox/Worker・動的 provisioning・Retry UI・周期対合 | C37: ⚪ 保留 | D37: —（P0 の前置条件ではない） | E37: REQ-037/038・RULE-10 UI | F37: ⚪ 保留
A39: ■ CHK-01 内部 ID（5 系列・引用時は必ず CHK-01 限定符を付す） | F39: 实施状态
A40: C-1〜C-8 | B40: 契約凍結事項（§3） | C40: tech-decisions G7 行が「CHK-01 C-3」形式で引用 | F40: ✅ 全決定済（2026-09-01・CHK-01 C-1〜C-8） | G40: P0-2
A41: B-1〜B-3 | B41: migration 実施・差分レビュー（§4） | F41: ✅ 実施済（2026-09-02・71c88c8） | G41: P0-2
A42: S-1〜S-5 | B42: SF 側実施項（§5）※画面 S-01〜11 と前綴衝突 | C42: ID 台账 §5.4 参照 | F42: ✅ 実施済（2026-09-02・aec1bf4/f020618/bc7a4ac） | G42: P0-2/P0-4
A43: D-1〜D-5 | B43: 既存文書回写事項（§6） | F43: ✅ 全実施（D-1〜D-5・2026-09-02） | G43: —（回写済）
A44: G-1〜G-3 | B44: gate 判定（§7）※G 寄存器 G1〜G7 と前綴衝突 | C44: 連字符有無が口徑差 | F44: ✅ G-1〜G-3 通過（2026-09-02・G-3 確定） | G44: P0-2

Sheet 13.文書ID台帳
A1: 文書 ID 台帳（IDR-01 §2.1/§3 出典）
A2: ◆＝定義源（采番処）。パスは docs/asset 相対。無 ID 文書 9 件は「—（無 ID）」行で収容。
A3: 文書ID | B3: ファイル（docs/asset 相対） | C3: 定義系列（◆＝定義源） | D3: 实施状态
A4: RD-01 | B4: requirement-definition/01_要件一覧.md | C4: REQ ◆ | D4: ✅ 作成済
A5: RD-02 | B5: requirement-definition/02_非機能要件一覧.md | C5: NFR ◆ | D5: ✅ 作成済
A6: RD-03 | B6: requirement-definition/03_業務一覧.md | C6: BIZ ◆ | D6: ✅ 作成済
A7: RD-04 | B7: requirement-definition/04_業務フロー.md | C7: 図1〜7（局所） | D7: ✅ 作成済
A8: RD-05 | B8: requirement-definition/05_業務ルール一覧.md | C8: RULE ◆ | D8: ✅ 作成済
A9: RD-06 | B9: requirement-definition/06_用語集.md | C9: TERM ◆ | D9: ✅ 作成済
A10: RD-07 | B10: requirement-definition/07_システム化範囲.md | C10: — | D10: ✅ 作成済
A11: RD-08 | B11: requirement-definition/08_ToBe業務モデルと現状課題.md | C11: ISS ◆（孤児系列） | D11: ✅ 作成済
A12: BD-01 | B12: basic-design/system-architecture.md | C12: A1〜A4 ◆ | D12: ✅ 作成済
A13: BD-02 | B13: basic-design/function-list.md | C13: F ◆ | D13: ✅ 作成済
A14: BD-03 | B14: basic-design/function-design.md | C14: — | D14: ✅ 作成済
... A39: —（無 ID） | B39: p0-2/interview-portfolio-req033-decision-record.md | C39: G（局所） | D39: ✅ 作成済（無 ID）

Sheet 14.要件×機能行列
A1: 要件 × 機能 カバレッジ行列
A2: 行=要件、列=機能。交叉格用下拉填「○」。蓝色=已建立对应。右侧合計为 0 的行会标红，说明该要件无人承接。
A3: 要件＼機能 | B3: =IF('3.機能一覧'!A4="","",'3.機能一覧'!A4) | C3: =IF('3.機能一覧'!A5="","",'3.機能一覧'!A5) | D3: =IF('3.機能一覧'!A6="","",'3.機能一覧'!A6) | E3: =IF('3.機能一覧'!A7="","",'3.機能一覧'!A7) | F3: =IF('3.機能一覧'!A8="","",'3.機能一覧'!A8) | G3: =IF('3.機能一覧'!A9="","",'3.機能一覧'!A9) | H3: =IF('3.機能一覧'!A10="","",'3.機能一覧'!A10) | I3: =IF('3.機能一覧'!A11="","",'3.機能一覧'!A11) | J3: =IF('3.機能一覧'!A12="","",'3.機能一覧'!A12) | K3: =IF('3.機能一覧'!A13="","",'3.機能一覧'!A13) | L3: =IF('3.機能一覧'!A14="","",'3.機能一覧'!A14) | M3: =IF('3.機能一覧'!A15="","",'3.機能一覧'!A15) | N3: =IF('3.機能一覧'!A16="","",'3.機能一覧'!A16) | O3: =IF('3.機能一覧'!A17="","",'3.機能一覧'!A17) | P3: =IF('3.機能一覧'!A18="","",'3.機能一覧'!A18) | Q3: =IF('3.機能一覧'!A19="","",'3.機能一覧'!A19) | R3: =IF('3.機能一覧'!A20="","",'3.機能一覧'!A20) | S3: =IF('3.機能一覧'!A21="","",'3.機能一覧'!A21) | T3: =IF('3.機能一覧'!A22="","",'3.機能一覧'!A22) | U3: =IF('3.機能一覧'!A23="","",'3.機能一覧'!A23) | V3: =IF('3.機能一覧'!A24="","",'3.機能一覧'!A24) | W3: =IF('3.機能一覧'!A25="","",'3.機能一覧'!A25) | X3: =IF('3.機能一覧'!A26="","",'3.機能一覧'!A26) | Y3: =IF('3.機能一覧'!A27="","",'3.機能一覧'!A27) | Z3: =IF('3.機能一覧'!A28="","",'3.機能一覧'!A28) | AA3: =IF('3.機能一覧'!A29="","",'3.機能一覧'!A29) | AB3: =IF('3.機能一覧'!A30="","",'3.機能一覧'!A30) | AC3: =IF('3.機能一覧'!A31="","",'3.機能一覧'!A31) | AD3: =IF('3.機能一覧'!A32="","",'3.機能一覧'!A32) | AE3: =IF('3.機能一覧'!A33="","",'3.機能一覧'!A33) | AF3: =IF('3.機能一覧'!A34="","",'3.機能一覧'!A34) | AG3: =IF('3.機能一覧'!A35="","",'3.機能一覧'!A35) | AH3: =IF('3.機能一覧'!A36="","",'3.機能一覧'!A36) | AI3: =IF('3.機能一覧'!A37="","",'3.機能一覧'!A37) | AJ3: =IF('3.機能一覧'!A38="","",'3.機能一覧'!A38) | AK3: =IF('3.機能一覧'!A39="","",'3.機能一覧'!A39) | AL3: =IF('3.機能一覧'!A40="","",'3.機能一覧'!A40) | AM3: =IF('3.機能一覧'!A41="","",'3.機能一覧'!A41) | AN3: =IF('3.機能一覧'!A42="","",'3.機能一覧'!A42) | AO3: =IF('3.機能一覧'!A43="","",'3.機能一覧'!A43) | AP3: =IF('3.機能一覧'!A44="","",'3.機能一覧'!A44) | AQ3: =IF('3.機能一覧'!A45="","",'3.機能一覧'!A45) | AR3: =IF('3.機能一覧'!A46="","",'3.機能一覧'!A46) | AS3: =IF('3.機能一覧'!A47="","",'3.機能一覧'!A47) | AT3: =IF('3.機能一覧'!A48="","",'3.機能一覧'!A48) | AU3: =IF('3.機能一覧'!A49="","",'3.機能一覧'!A49) | AV3: =IF('3.機能一覧'!A50="","",'3.機能一覧'!A50) | AW3: =IF('3.機能一覧'!A51="","",'3.機能一覧'!A51) | AX3: =IF('3.機能一覧'!A52="","",'3.機能一覧'!A52) | AY3: =IF('3.機能一覧'!A53="","",'3.機能一覧'!A53) | AZ3: =IF('3.機能一覧'!A54="","",'3.機能一覧'!A54) | BA3: =IF('3.機能一覧'!A55="","",'3.機能一覧'!A55) | BB3: =IF('3.機能一覧'!A56="","",'3.機能一覧'!A56) | BC3: =IF('3.機能一覧'!A57="","",'3.機能一覧'!A57) | BD3: =IF('3.機能一覧'!A58="","",'3.機能一覧'!A58) | BE3: =IF('3.機能一覧'!A59="","",'3.機能一覧'!A59) | BF3: =IF('3.機能一覧'!A60="","",'3.機能一覧'!A60) | BG3: =IF('3.機能一覧'!A61="","",'3.機能一覧'!A61) | BH3: =IF('3.機能一覧'!A62="","",'3.機能一覧'!A62) | BI3: =IF('3.機能一覧'!A63="","",'3.機能一覧'!A63) | BJ3: 合計 | BK3: 判定 | BL3: 工程
A4: =IF('2.要件一覧'!A4="","",'2.要件一覧'!A4) | C4: ○ | BJ4: =IF($A4="","",SUMPRODUCT(($B$3:$BI$3<>"")*($B4:BI4="○"))) | BK4: =IF($A4="","",IF($BJ4=0,"⚠ 未割当","OK")) | BL4: =IF($A4="","",'2.要件一覧'!$L4)
